Workbook

Sheet README
A1: Lineage Schedule v2 — 사용 안내
A3: 탭 구성
A4: • Client Board / Farming Board — 고객 계정 / 농장 계정 주간 보기 (수식, 직접 수정 금지). B2에 주 시작 일요일 입력하면 다른 주 조회
A5: • Schedule — 원장. 1행 = 계정 × 날짜 × 시프트(Slot). 시간·플레이어·사냥터·KPI·골드·물약을 여기서 입력/수정 (필터 사용)
A6: - Time: HH:MM-HH:MM 또는 OFF. Hours/Week/Key/Display/Maint Hrs/Pay Week(P~U열)는 자동 계산 — 건드리지 말 것
A7: • Planner — 기간 스케줄 입력 (예: 10/1~10/31 평일 09:00-17:00 Cejay). 행을 채우고 디스코드 /plan → 미리보기 → Apply
A8: • Settings — 정기점검 요일·시간 (기본 수요일 05:00-09:00). 겹치는 시프트 시간은 Hours에서 자동 차감
A9: • Accounts — 계정 마스터. Type=Client(고객) / Farming(농장), Status=Active/Paused/Inactive, Customer=고객명, SalesRep=담당 영업
A10: • TL Board / TL Schedule — 팀 리더 근무표 (Board = 주간 보기, Schedule = 입력: 근무시간·출근). TL OT는 Overtime 탭 (Role=TL). 이관: Week 16~39 + 다음 주 초안
A11: • Overtime / Incentives / Death Penalty — 매니저 기록 로그 (디스코드 봇 /ot /incentive /penalty 로 입력, 직접 입력도 가능). Performance Pay — 인센티브 기준표
A12: • Payroll — 2주 단위(월~일 × 2, 예: 9/21~10/4) 직원별 1·2주차 근무시간, OT, 페널티, 지급 시간, 인센티브 합계, 담당 캐릭터 자동 집계. B2에 기간 시작일 입력하면 과거 기간 조회 / Payroll History — 기존 수기 Payroll(W19·20·33·34)
A13: • Glossary — 봇 용어 사전 / EventLog — 봇 기록(질문·재접속·정보)
... A28: Taejo: 마스터=Client / 시트 배치=Farming

Sheet Planner
A1: Account | B1: Slot | C1: Days | D1: Time | E1: Player | F1: Hunting Ground | G1: From | H1: To | I1: Status
A2: ADA | B2: 1 | C2: Mon-Fri | D2: 09:00-17:00 | E2: Cejay | G2: 2026-10-01 | H2: 2026-10-31 | I2: EXAMPLE — delete this row. Blank Player/Ground = keep what's there. Days: Daily, Mon-Fri, Weekends, Mon,Wed,Fri. Then run /plan in Discord.

Sheet Client Board
A1: CLIENT (고객) ACCOUNTS — Weekly Board
A2: Week start (Sun): | B2: =TEXT(TODAY()-WEEKDAY(TODAY())+1,"yyyy-mm-dd") | D2: ← 다른 주를 보려면 일요일 날짜(yyyy-mm-dd)를 직접 입력. 이 탭은 보기 전용 — 수정은 Schedule 탭에서.
A3: Account | B3: Slot | C3: Sun | D3: Mon | E3: Tue | F3: Wed | G3: Thu | H3: Fri | I3: Sat | J3: Hours
A4: date → | C4: =TEXT(DATEVALUE($B$2)+0,"yyyy-mm-dd") | D4: =TEXT(DATEVALUE($B$2)+1,"yyyy-mm-dd") | E4: =TEXT(DATEVALUE($B$2)+2,"yyyy-mm-dd") | F4: =TEXT(DATEVALUE($B$2)+3,"yyyy-mm-dd") | G4: =TEXT(DATEVALUE($B$2)+4,"yyyy-mm-dd") | H4: =TEXT(DATEVALUE($B$2)+5,"yyyy-mm-dd") | I4: =TEXT(DATEVALUE($B$2)+6,"yyyy-mm-dd")
A5: ADA | B5: 1 | C5: =ARRAYFORMULA(IF($A5:$A300="","",IFERROR(VLOOKUP(C$4&"|"&$A5:$A300&"|"&$B5:$B300,Schedule!$R:$S,2,FALSE),""))) | D5: =ARRAYFORMULA(IF($A5:$A300="","",IFERROR(VLOOKUP(D$4&"|"&$A5:$A300&"|"&$B5:$B300,Schedule!$R:$S,2,FALSE),""))) | E5: =ARRAYFORMULA(IF($A5:$A300="","",IFERROR(VLOOKUP(E$4&"|"&$A5:$A300&"|"&$B5:$B300,Schedule!$R:$S,2,FALSE),""))) | F5: =ARRAYFORMULA(IF($A5:$A300="","",IFERROR(VLOOKUP(F$4&"|"&$A5:$A300&"|"&$B5:$B300,Schedule!$R:$S,2,FALSE),""))) | G5: =ARRAYFORMULA(IF($A5:$A300="","",IFERROR(VLOOKUP(G$4&"|"&$A5:$A300&"|"&$B5:$B300,Schedule!$R:$S,2,FALSE),""))) | H5: =ARRAYFORMULA(IF($A5:$A300="","",IFERROR(VLOOKUP(H$4&"|"&$A5:$A300&"|"&$B5:$B300,Schedule!$R:$S,2,FALSE),""))) | I5: =ARRAYFORMULA(IF($A5:$A300="","",IFERROR(VLOOKUP(I$4&"|"&$A5:$A300&"|"&$B5:$B300,Schedule!$R:$S,2,FALSE),""))) | J5: =IF($A5="","",SUMIFS(Schedule!$P:$P,Schedule!$Q:$Q,$B$2,Schedule!$D:$D,$A5,Schedule!$E:$E,$B5))
A6: ADA | B6: 2 | J6: =IF($A6="","",SUMIFS(Schedule!$P:$P,Schedule!$Q:$Q,$B$2,Schedule!$D:$D,$A6,Schedule!$E:$E,$B6))
A7: Alex | B7: 1 | J7: =IF($A7="","",SUMIFS(Schedule!$P:$P,Schedule!$Q:$Q,$B$2,Schedule!$D:$D,$A7,Schedule!$E:$E,$B7))
A8: Alex | B8: 2 | J8: =IF($A8="","",SUMIFS(Schedule!$P:$P,Schedule!$Q:$Q,$B$2,Schedule!$D:$D,$A8,Schedule!$E:$E,$B8))
A9: Alex | B9: 3 | J9: =IF($A9="","",SUMIFS(Schedule!$P:$P,Schedule!$Q:$Q,$B$2,Schedule!$D:$D,$A9,Schedule!$E:$E,$B9))
A10: Beongaebul | B10: 1 | J10: =IF($A10="","",SUMIFS(Schedule!$P:$P,Schedule!$Q:$Q,$B$2,Schedule!$D:$D,$A10,Schedule!$E:$E,$B10))
A11: Captain | B11: 1 | J11: =IF($A11="","",SUMIFS(Schedule!$P:$P,Schedule!$Q:$Q,$B$2,Schedule!$D:$D,$A11,Schedule!$E:$E,$B11))
A12: Captain | B12: 2 | J12: =IF($A12="","",SUMIFS(Schedule!$P:$P,Schedule!$Q:$Q,$B$2,Schedule!$D:$D,$A12,Schedule!$E:$E,$B12))
A13: Dalo | B13: 1 | J13: =IF($A13="","",SUMIFS(Schedule!$P:$P,Schedule!$Q:$Q,$B$2,Schedule!$D:$D,$A13,Schedule!$E:$E,$B13))
A14: Dalo | B14: 2 | J14: =IF($A14="","",SUMIFS(Schedule!$P:$P,Schedule!$Q:$Q,$B$2,Schedule!$D:$D,$A14,Schedule!$E:$E,$B14))
A15: Dalo | B15: 3 | J15: =IF($A15="","",SUMIFS(Schedule!$P:$P,Schedule!$Q:$Q,$B$2,Schedule!$D:$D,$A15,Schedule!$E:$E,$B15))
A16: Dodam | B16: 1 | J16: =IF($A16="","",SUMIFS(Schedule!$P:$P,Schedule!$Q:$Q,$B$2,Schedule!$D:$D,$A16,Schedule!$E:$E,$B16))
A17: Dodam | B17: 2 | J17: =IF($A17="","",SUMIFS(Schedule!$P:$P,Schedule!$Q:$Q,$B$2,Schedule!$D:$D,$A17,Schedule!$E:$E,$B17))
... A58: Zombie | B58: 3 | J58: =IF($A58="","",SUMIFS(Schedule!$P:$P,Schedule!$Q:$Q,$B$2,Schedule!$D:$D,$A58,Schedule!$E:$E,$B58))
J59: =IF($A59="","",SUMIFS(Schedule!$P:$P,Schedule!$Q:$Q,$B$2,Schedule!$D:$D,$A59,Schedule!$E:$E,$B59))
J60: =IF($A60="","",SUMIFS(Schedule!$P:$P,Schedule!$Q:$Q,$B$2,Schedule!$D:$D,$A60,Schedule!$E:$E,$B60))
J61: =IF($A61="","",SUMIFS(Schedule!$P:$P,Schedule!$Q:$Q,$B$2,Schedule!$D:$D,$A61,Schedule!$E:$E,$B61))
J62: =IF($A62="","",SUMIFS(Schedule!$P:$P,Schedule!$Q:$Q,$B$2,Schedule!$D:$D,$A62,Schedule!$E:$E,$B62))
J63: =IF($A63="","",SUMIFS(Schedule!$P:$P,Schedule!$Q:$Q,$B$2,Schedule!$D:$D,$A63,Schedule!$E:$E,$B63))
J64: =IF($A64="","",SUMIFS(Schedule!$P:$P,Schedule!$Q:$Q,$B$2,Schedule!$D:$D,$A64,Schedule!$E:$E,$B64))
J65: =IF($A65="","",SUMIFS(Schedule!$P:$P,Schedule!$Q:$Q,$B$2,Schedule!$D:$D,$A65,Schedule!$E:$E,$B65))
J66: =IF($A66="","",SUMIFS(Schedule!$P:$P,Schedule!$Q:$Q,$B$2,Schedule!$D:$D,$A66,Schedule!$E:$E,$B66))
J67: =IF($A67="","",SUMIFS(Schedule!$P:$P,Schedule!$Q:$Q,$B$2,Schedule!$D:$D,$A67,Schedule!$E:$E,$B67))
J68: =IF($A68="","",SUMIFS(Schedule!$P:$P,Schedule!$Q:$Q,$B$2,Schedule!$D:$D,$A68,Schedule!$E:$E,$B68))
J69: =IF($A69="","",SUMIFS(Schedule!$P:$P,Schedule!$Q:$Q,$B$2,Schedule!$D:$D,$A69,Schedule!$E:$E,$B69))
J70: =IF($A70="","",SUMIFS(Schedule!$P:$P,Schedule!$Q:$Q,$B$2,Schedule!$D:$D,$A70,Schedule!$E:$E,$B70))
... J300: =IF($A300="","",SUMIFS(Schedule!$P:$P,Schedule!$Q:$Q,$B$2,Schedule!$D:$D,$A300,Schedule!$E:$E,$B300))

Sheet Farming Board
A1: FARMING (농장) ACCOUNTS — Weekly Board
A2: Week start (Sun): | B2: =TEXT(TODAY()-WEEKDAY(TODAY())+1,"yyyy-mm-dd") | D2: ← 다른 주를 보려면 일요일 날짜(yyyy-mm-dd)를 직접 입력. 이 탭은 보기 전용 — 수정은 Schedule 탭에서.
A3: Account | B3: Slot | C3: Sun | D3: Mon | E3: Tue | F3: Wed | G3: Thu | H3: Fri | I3: Sat | J3: Hours
A4: date → | C4: =TEXT(DATEVALUE($B$2)+0,"yyyy-mm-dd") | D4: =TEXT(DATEVALUE($B$2)+1,"yyyy-mm-dd") | E4: =TEXT(DATEVALUE($B$2)+2,"yyyy-mm-dd") | F4: =TEXT(DATEVALUE($B$2)+3,"yyyy-mm-dd") | G4: =TEXT(DATEVALUE($B$2)+4,"yyyy-mm-dd") | H4: =TEXT(DATEVALUE($B$2)+5,"yyyy-mm-dd") | I4: =TEXT(DATEVALUE($B$2)+6,"yyyy-mm-dd")
A5: Kangaroo | B5: 1 | C5: =ARRAYFORMULA(IF($A5:$A300="","",IFERROR(VLOOKUP(C$4&"|"&$A5:$A300&"|"&$B5:$B300,Schedule!$R:$S,2,FALSE),""))) | D5: =ARRAYFORMULA(IF($A5:$A300="","",IFERROR(VLOOKUP(D$4&"|"&$A5:$A300&"|"&$B5:$B300,Schedule!$R:$S,2,FALSE),""))) | E5: =ARRAYFORMULA(IF($A5:$A300="","",IFERROR(VLOOKUP(E$4&"|"&$A5:$A300&"|"&$B5:$B300,Schedule!$R:$S,2,FALSE),""))) | F5: =ARRAYFORMULA(IF($A5:$A300="","",IFERROR(VLOOKUP(F$4&"|"&$A5:$A300&"|"&$B5:$B300,Schedule!$R:$S,2,FALSE),""))) | G5: =ARRAYFORMULA(IF($A5:$A300="","",IFERROR(VLOOKUP(G$4&"|"&$A5:$A300&"|"&$B5:$B300,Schedule!$R:$S,2,FALSE),""))) | H5: =ARRAYFORMULA(IF($A5:$A300="","",IFERROR(VLOOKUP(H$4&"|"&$A5:$A300&"|"&$B5:$B300,Schedule!$R:$S,2,FALSE),""))) | I5: =ARRAYFORMULA(IF($A5:$A300="","",IFERROR(VLOOKUP(I$4&"|"&$A5:$A300&"|"&$B5:$B300,Schedule!$R:$S,2,FALSE),""))) | J5: =IF($A5="","",SUMIFS(Schedule!$P:$P,Schedule!$Q:$Q,$B$2,Schedule!$D:$D,$A5,Schedule!$E:$E,$B5))
A6: Kangaroo | B6: 2 | J6: =IF($A6="","",SUMIFS(Schedule!$P:$P,Schedule!$Q:$Q,$B$2,Schedule!$D:$D,$A6,Schedule!$E:$E,$B6))
A7: Kangaroo | B7: 3 | J7: =IF($A7="","",SUMIFS(Schedule!$P:$P,Schedule!$Q:$Q,$B$2,Schedule!$D:$D,$A7,Schedule!$E:$E,$B7))
A8: Kyoryu | B8: 1 | J8: =IF($A8="","",SUMIFS(Schedule!$P:$P,Schedule!$Q:$Q,$B$2,Schedule!$D:$D,$A8,Schedule!$E:$E,$B8))
A9: Kyoryu | B9: 2 | J9: =IF($A9="","",SUMIFS(Schedule!$P:$P,Schedule!$Q:$Q,$B$2,Schedule!$D:$D,$A9,Schedule!$E:$E,$B9))
A10: Kyoryu | B10: 3 | J10: =IF($A10="","",SUMIFS(Schedule!$P:$P,Schedule!$Q:$Q,$B$2,Schedule!$D:$D,$A10,Schedule!$E:$E,$B10))
A11: Marcelo | B11: 1 | J11: =IF($A11="","",SUMIFS(Schedule!$P:$P,Schedule!$Q:$Q,$B$2,Schedule!$D:$D,$A11,Schedule!$E:$E,$B11))
A12: Marcelo | B12: 2 | J12: =IF($A12="","",SUMIFS(Schedule!$P:$P,Schedule!$Q:$Q,$B$2,Schedule!$D:$D,$A12,Schedule!$E:$E,$B12))
A13: Marcelo | B13: 3 | J13: =IF($A13="","",SUMIFS(Schedule!$P:$P,Schedule!$Q:$Q,$B$2,Schedule!$D:$D,$A13,Schedule!$E:$E,$B13))
A14: OldBlood | B14: 1 | J14: =IF($A14="","",SUMIFS(Schedule!$P:$P,Schedule!$Q:$Q,$B$2,Schedule!$D:$D,$A14,Schedule!$E:$E,$B14))
A15: Pele | B15: 1 | J15: =IF($A15="","",SUMIFS(Schedule!$P:$P,Schedule!$Q:$Q,$B$2,Schedule!$D:$D,$A15,Schedule!$E:$E,$B15))
A16: Pele | B16: 2 | J16: =IF($A16="","",SUMIFS(Schedule!$P:$P,Schedule!$Q:$Q,$B$2,Schedule!$D:$D,$A16,Schedule!$E:$E,$B16))
A17: Pele | B17: 3 | J17: =IF($A17="","",SUMIFS(Schedule!$P:$P,Schedule!$Q:$Q,$B$2,Schedule!$D:$D,$A17,Schedule!$E:$E,$B17))
... A32: Taejo | B32: 3 | J32: =IF($A32="","",SUMIFS(Schedule!$P:$P,Schedule!$Q:$Q,$B$2,Schedule!$D:$D,$A32,Schedule!$E:$E,$B32))
J33: =IF($A33="","",SUMIFS(Schedule!$P:$P,Schedule!$Q:$Q,$B$2,Schedule!$D:$D,$A33,Schedule!$E:$E,$B33))
J34: =IF($A34="","",SUMIFS(Schedule!$P:$P,Schedule!$Q:$Q,$B$2,Schedule!$D:$D,$A34,Schedule!$E:$E,$B34))
J35: =IF($A35="","",SUMIFS(Schedule!$P:$P,Schedule!$Q:$Q,$B$2,Schedule!$D:$D,$A35,Schedule!$E:$E,$B35))
J36: =IF($A36="","",SUMIFS(Schedule!$P:$P,Schedule!$Q:$Q,$B$2,Schedule!$D:$D,$A36,Schedule!$E:$E,$B36))
J37: =IF($A37="","",SUMIFS(Schedule!$P:$P,Schedule!$Q:$Q,$B$2,Schedule!$D:$D,$A37,Schedule!$E:$E,$B37))
J38: =IF($A38="","",SUMIFS(Schedule!$P:$P,Schedule!$Q:$Q,$B$2,Schedule!$D:$D,$A38,Schedule!$E:$E,$B38))
J39: =IF($A39="","",SUMIFS(Schedule!$P:$P,Schedule!$Q:$Q,$B$2,Schedule!$D:$D,$A39,Schedule!$E:$E,$B39))
J40: =IF($A40="","",SUMIFS(Schedule!$P:$P,Schedule!$Q:$Q,$B$2,Schedule!$D:$D,$A40,Schedule!$E:$E,$B40))
J41: =IF($A41="","",SUMIFS(Schedule!$P:$P,Schedule!$Q:$Q,$B$2,Schedule!$D:$D,$A41,Schedule!$E:$E,$B41))
J42: =IF($A42="","",SUMIFS(Schedule!$P:$P,Schedule!$Q:$Q,$B$2,Schedule!$D:$D,$A42,Schedule!$E:$E,$B42))
J43: =IF($A43="","",SUMIFS(Schedule!$P:$P,Schedule!$Q:$Q,$B$2,Schedule!$D:$D,$A43,Schedule!$E:$E,$B43))
J44: =IF($A44="","",SUMIFS(Schedule!$P:$P,Schedule!$Q:$Q,$B$2,Schedule!$D:$D,$A44,Schedule!$E:$E,$B44))
... J300: =IF($A300="","",SUMIFS(Schedule!$P:$P,Schedule!$Q:$Q,$B$2,Schedule!$D:$D,$A300,Schedule!$E:$E,$B300))

Sheet TL Board
A1: TEAM LEADER — Weekly Schedule
A2: Week start (Sun): | B2: =TEXT(TODAY()-WEEKDAY(TODAY())+1,"yyyy-mm-dd") | D2: ← 셀 = 근무시간 / 출근. OT Hrs = Overtime 탭 합계. 보기 전용 — 입력은 'TL Schedule' 탭에서.
A3: Leader | B3: Sun | C3: Mon | D3: Tue | E3: Wed | F3: Thu | G3: Fri | H3: Sat | I3: OT Hrs
B4: =TEXT(DATEVALUE($B$2)+0,"yyyy-mm-dd") | C4: =TEXT(DATEVALUE($B$2)+1,"yyyy-mm-dd") | D4: =TEXT(DATEVALUE($B$2)+2,"yyyy-mm-dd") | E4: =TEXT(DATEVALUE($B$2)+3,"yyyy-mm-dd") | F4: =TEXT(DATEVALUE($B$2)+4,"yyyy-mm-dd") | G4: =TEXT(DATEVALUE($B$2)+5,"yyyy-mm-dd") | H4: =TEXT(DATEVALUE($B$2)+6,"yyyy-mm-dd")
A5: Alyssa | B5: =ARRAYFORMULA(IF($A5:$A300="","",IFERROR(VLOOKUP(B$4&"|"&$A5:$A300,'TL Schedule'!$H:$I,2,FALSE),""))) | C5: =ARRAYFORMULA(IF($A5:$A300="","",IFERROR(VLOOKUP(C$4&"|"&$A5:$A300,'TL Schedule'!$H:$I,2,FALSE),""))) | D5: =ARRAYFORMULA(IF($A5:$A300="","",IFERROR(VLOOKUP(D$4&"|"&$A5:$A300,'TL Schedule'!$H:$I,2,FALSE),""))) | E5: =ARRAYFORMULA(IF($A5:$A300="","",IFERROR(VLOOKUP(E$4&"|"&$A5:$A300,'TL Schedule'!$H:$I,2,FALSE),""))) | F5: =ARRAYFORMULA(IF($A5:$A300="","",IFERROR(VLOOKUP(F$4&"|"&$A5:$A300,'TL Schedule'!$H:$I,2,FALSE),""))) | G5: =ARRAYFORMULA(IF($A5:$A300="","",IFERROR(VLOOKUP(G$4&"|"&$A5:$A300,'TL Schedule'!$H:$I,2,FALSE),""))) | H5: =ARRAYFORMULA(IF($A5:$A300="","",IFERROR(VLOOKUP(H$4&"|"&$A5:$A300,'TL Schedule'!$H:$I,2,FALSE),""))) | I5: =IF($A5="","",SUMIFS(Overtime!$H:$H,Overtime!$B:$B,$A5,Overtime!$M:$M,$B$2))
A6: John Manuel | I6: =IF($A6="","",SUMIFS(Overtime!$H:$H,Overtime!$B:$B,$A6,Overtime!$M:$M,$B$2))
A7: Micko Tanedo | I7: =IF($A7="","",SUMIFS(Overtime!$H:$H,Overtime!$B:$B,$A7,Overtime!$M:$M,$B$2))
I8: =IF($A8="","",SUMIFS(Overtime!$H:$H,Overtime!$B:$B,$A8,Overtime!$M:$M,$B$2))
I9: =IF($A9="","",SUMIFS(Overtime!$H:$H,Overtime!$B:$B,$A9,Overtime!$M:$M,$B$2))
I10: =IF($A10="","",SUMIFS(Overtime!$H:$H,Overtime!$B:$B,$A10,Overtime!$M:$M,$B$2))
I11: =IF($A11="","",SUMIFS(Overtime!$H:$H,Overtime!$B:$B,$A11,Overtime!$M:$M,$B$2))
I12: =IF($A12="","",SUMIFS(Overtime!$H:$H,Overtime!$B:$B,$A12,Overtime!$M:$M,$B$2))
I13: =IF($A13="","",SUMIFS(Overtime!$H:$H,Overtime!$B:$B,$A13,Overtime!$M:$M,$B$2))
I14: =IF($A14="","",SUMIFS(Overtime!$H:$H,Overtime!$B:$B,$A14,Overtime!$M:$M,$B$2))
I15: =IF($A15="","",SUMIFS(Overtime!$H:$H,Overtime!$B:$B,$A15,Overtime!$M:$M,$B$2))
I16: =IF($A16="","",SUMIFS(Overtime!$H:$H,Overtime!$B:$B,$A16,Overtime!$M:$M,$B$2))
I17: =IF($A17="","",SUMIFS(Overtime!$H:$H,Overtime!$B:$B,$A17,Overtime!$M:$M,$B$2))
I18: =IF($A18="","",SUMIFS(Overtime!$H:$H,Overtime!$B:$B,$A18,Overtime!$M:$M,$B$2))
I19: =IF($A19="","",SUMIFS(Overtime!$H:$H,Overtime!$B:$B,$A19,Overtime!$M:$M,$B$2))
... I300: =IF($A300="","",SUMIFS(Overtime!$H:$H,Overtime!$B:$B,$A300,Overtime!$M:$M,$B$2))

Sheet Schedule
A1: Date | B1: Day | C1: Type | D1: Account | E1: Slot | F1: Time | G1: Player | H1: Hunting Ground | I1: KPI | J1: Gold | K1: E-Red | L1: E-Green | M1: E-Purple | N1: Note | O1: Updated | P1: Hours | Q1: Week | R1: Key | S1: Display | T1: Maint Hrs | U1: Pay Week
A2: 2026-09-20 | B2: Sun | C2: Client | D2: ADA | E2: 1 | F2: 09:00-17:00 | G2: Cejay | P2: =ARRAYFORMULA(IF(A2:A50000="",,IF((F2:F50000="OFF")+(G2:G50000=""),0,IFERROR(MOD((VALUE(REGEXEXTRACT(F2:F50000,"-(\d+):"))+VALUE(REGEXEXTRACT(F2:F50000,"-\d+:(\d+)"))/60)-(VALUE(REGEXEXTRACT(F2:F50000,"^(\d+):"))+VALUE(REGEXEXTRACT(F2:F50000,"^\d+:(\d+)"))/60),24)-T2:T50000,0)))) | Q2: =ARRAYFORMULA(IF(A2:A50000="",,TEXT(IF(ISNUMBER(A2:A50000),A2:A50000,IFERROR(DATEVALUE(A2:A50000)))-WEEKDAY(IF(ISNUMBER(A2:A50000),A2:A50000,IFERROR(DATEVALUE(A2:A50000))))+1,"yyyy-mm-dd"))) | R2: =ARRAYFORMULA(IF(A2:A50000="",,TEXT(IF(ISNUMBER(A2:A50000),A2:A50000,IFERROR(DATEVALUE(A2:A50000))),"yyyy-mm-dd")&"|"&D2:D50000&"|"&E2:E50000)) | S2: =ARRAYFORMULA(IF(A2:A50000="",,IF(F2:F50000="OFF","OFF",F2:F50000&IF(G2:G50000="","",CHAR(10)&G2:G50000)&IF(H2:H50000="","",CHAR(10)&"@"&H2:H50000)&IF(T2:T50000>0,CHAR(10)&"⚙ maint -"&T2:T50000&"h","")))) | T2: =ARRAYFORMULA(IF(A2:A50000="",,IF(F2:F50000="OFF",0,IFERROR(IFERROR(IF(WEEKDAY(IF(ISNUMBER(A2:A50000),A2:A50000,IFERROR(DATEVALUE(A2:A50000))))=((FIND(LEFT('Settings'!$B$2,3),"SunMonTueWedThuFriSat")+2)/3),IF(IF(((VALUE(REGEXEXTRACT(F2:F50000,"^(\d+):"))+VALUE(REGEXEXTRACT(F2:F50000,"^\d+:(\d+)"))/60)+MOD((VALUE(REGEXEXTRACT(F2:F50000,"-(\d+):"))+VALUE(REGEXEXTRACT(F2:F50000,"-\d+:(\d+)"))/60)-(VALUE(REGEXEXTRACT(F2:F50000,"^(\d+):"))+VALUE(REGEXEXTRACT(F2:F50000,"^\d+:(\d+)"))/60),24))<(HOUR('Settings'!$B$4)+MINUTE('Settings'!$B$4)/60),((VALUE(REGEXEXTRACT(F2:F50000,"^(\d+):"))+VALUE(REGEXEXTRACT(F2:F50000,"^\d+:(\d+)"))/60)+MOD((VALUE(REGEXEXTRACT(F2:F50000,"-(\d+):"))+VALUE(REGEXEXTRACT(F2:F50000,"-\d+:(\d+)"))/60)-(VALUE(REGEXEXTRACT(F2:F50000,"^(\d+):"))+VALUE(REGEXEXTRACT(F2:F50000,"^\d+:(\d+)"))/60),24)),(HOUR('Settings'!$B$4)+MINUTE('Settings'!$B$4)/60))-IF((VALUE(REGEXEXTRACT(F2:F50000,"^(\d+):"))+VALUE(REGEXEXTRACT(F2:F50000,"^\d+:(\d+)"))/60)>(HOUR('Settings'!$B$3)+MINUTE('Settings'!$B$3)/60),(VALUE(REGEXEXTRACT(F2:F50000,"^(\d+):"))+VALUE(REGEXEXTRACT(F2:F50000,"^\d+:(\d+)"))/60),(HOUR('Settings'!$B$3)+MINUTE('Settings'!$B$3)/60))>0,IF(((VALUE(REGEXEXTRACT(F2:F50000,"^(\d+):"))+VALUE(REGEXEXTRACT(F2:F50000,"^\d+:(\d+)"))/60)+MOD((VALUE(REGEXEXTRACT(F2:F50000,"-(\d+):"))+VALUE(REGEXEXTRACT(F2:F50000,"-\d+:(\d+)"))/60)-(VALUE(REGEXEXTRACT(F2:F50000,"^(\d+):"))+VALUE(REGEXEXTRACT(F2:F50000,"^\d+:(\d+)"))/60),24))<(HOUR('Settings'!$B$4)+MINUTE('Settings'!$B$4)/60),((VALUE(REGEXEXTRACT(F2:F50000,"^(\d+):"))+VALUE(REGEXEXTRACT(F2:F50000,"^\d+:(\d+)"))/60)+MOD((VALUE(REGEXEXTRACT(F2:F50000,"-(\d+):"))+VALUE(REGEXEXTRACT(F2:F50000,"-\d+:(\d+)"))/60)-(VALUE(REGEXEXTRACT(F2:F50000,"^(\d+):"))+VALUE(REGEXEXTRACT(F2:F50000,"^\d+:(\d+)"))/60),24)),(HOUR('Settings'!$B$4)+MINUTE('Settings'!$B$4)/60))-IF((VALUE(REGEXEXTRACT(F2:F50000,"^(\d+):"))+VALUE(REGEXEXTRACT(F2:F50000,"^\d+:(\d+)"))/60)>(HOUR('Settings'!$B$3)+MINUTE('Settings'!$B$3)/60),(VALUE(REGEXEXTRACT(F2:F50000,"^(\d+):"))+VALUE(REGEXEXTRACT(F2:F50000,"^\d+:(\d+)"))/60),(HOUR('Settings'!$B$3)+MINUTE('Settings'!$B$3)/60)),0),0)+IF(WEEKDAY(IF(ISNUMBER(A2:A50000),A2:A50000,IFERROR(DATEVALUE(A2:A50000)))+1)=((FIND(LEFT('Settings'!$B$2,3),"SunMonTueWedThuFriSat")+2)/3),IF(IF(((VALUE(REGEXEXTRACT(F2:F50000,"^(\d+):"))+VALUE(REGEXEXTRACT(F2:F50000,"^\d+:(\d+)"))/60)+MOD((VALUE(REGEXEXTRACT(F2:F50000,"-(\d+):"))+VALUE(REGEXEXTRACT(F2:F50000,"-\d+:(\d+)"))/60)-(VALUE(REGEXEXTRACT(F2:F50000,"^(\d+):"))+VALUE(REGEXEXTRACT(F2:F50000,"^\d+:(\d+)"))/60),24))<(24+(HOUR('Settings'!$B$4)+MINUTE('Settings'!$B$4)/60)),((VALUE(REGEXEXTRACT(F2:F50000,"^(\d+):"))+VALUE(REGEXEXTRACT(F2:F50000,"^\d+:(\d+)"))/60)+MOD((VALUE(REGEXEXTRACT(F2:F50000,"-(\d+):"))+VALUE(REGEXEXTRACT(F2:F50000,"-\d+:(\d+)"))/60)-(VALUE(REGEXEXTRACT(F2:F50000,"^(\d+):"))+VALUE(REGEXEXTRACT(F2:F50000,"^\d+:(\d+)"))/60),24)),(24+(HOUR('Settings'!$B$4)+MINUTE('Settings'!$B$4)/60)))-IF((VALUE(REGEXEXTRACT(F2:F50000,"^(\d+):"))+VALUE(REGEXEXTRACT(F2:F50000,"^\d+:(\d+)"))/60)>(24+(HOUR('Settings'!$B$3)+MINUTE('Settings'!$B$3)/60)),(VALUE(REGEXEXTRACT(F2:F50000,"^(\d+):"))+VALUE(REGEXEXTRACT(F2:F50000,"^\d+:(\d+)"))/60),(24+(HOUR('Settings'!$B$3)+MINUTE('Settings'!$B$3)/60)))>0,IF(((VALUE(REGEXEXTRACT(F2:F50000,"^(\d+):"))+VALUE(REGEXEXTRACT(F2:F50000,"^\d+:(\d+)"))/60)+MOD((VALUE(REGEXEXTRACT(F2:F50000,"-(\d+):"))+VALUE(REGEXEXTRACT(F2:F50000,"-\d+:(\d+)"))/60)-(VALUE(REGEXEXTRACT(F2:F50000,"^(\d+):"))+VALUE(REGEXEXTRACT(F2:F50000,"^\d+:(\d+)"))/60),24))<(24+(HOUR('Settings'!$B$4)+MINUTE('Settings'!$B$4)/60)),((VALUE(REGEXEXTRACT(F2:F50000,"^(\d+):"))+VALUE(REGEXEXTRACT(F2:F50000,"^\d+:(\d+)"))/60)+MOD((VALUE(REGEXEXTRACT(F2:F50000,"-(\d+):"))+VALUE(REGEXEXTRACT(F2:F50000,"-\d+:(\d+)"))/60)-(VALUE(REGEXEXTRACT(F2:F50000,"^(\d+):"))+VALUE(REGEXEXTRACT(F2:F50000,"^\d+:(\d+)"))/60),24)),(24+(HOUR('Settings'!$B$4)+MINUTE('Settings'!$B$4)/60)))-IF((VALUE(REGEXEXTRACT(F2:F50000,"^(\d+):"))+VALUE(REGEXEXTRACT(F2:F50000,"^\d+:(\d+)"))/60)>(24+(HOUR('Settings'!$B$3)+MINUTE('Settings'!$B$3)/60)),(VALUE(REGEXEXTRACT(F2:F50000,"^(\d+):"))+VALUE(REGEXEXTRACT(F2:F50000,"^\d+:(\d+)"))/60),(24+(HOUR('Settings'!$B$3)+MINUTE('Settings'!$B$3)/60))),0),0),0),0)))) | U2: =ARRAYFORMULA(IF(A2:A50000="",,TEXT(IF(ISNUMBER(A2:A50000),A2:A50000,IFERROR(DATEVALUE(A2:A50000)))-WEEKDAY(IF(ISNUMBER(A2:A50000),A2:A50000,IFERROR(DATEVALUE(A2:A50000))),3),"yyyy-mm-dd")))
A3: 2026-09-20 | B3: Sun | C3: Client | D3: ADA | E3: 2 | F3: OFF
A4: 2026-09-20 | B4: Sun | C4: Client | D4: Alex | E4: 1 | F4: 08:00-16:00 | H4: Ivory Tower 4~5
A5: 2026-09-20 | B5: Sun | C5: Client | D5: Alex | E5: 2 | F5: OFF | H5: Ivory Tower 6~7
A6: 2026-09-20 | B6: Sun | C6: Client | D6: Alex | E6: 3 | F6: 01:00-08:00 | G6: Monteza | H6: Ivory Tower 4~5 | I6: 0.0097
A7: 2026-09-20 | B7: Sun | C7: Client | D7: Beongaebul | E7: 1 | F7: OFF
A8: 2026-09-20 | B8: Sun | C8: Client | D8: Captain | E8: 1 | F8: OFF
A9: 2026-09-20 | B9: Sun | C9: Client | D9: Captain | E9: 2 | F9: OFF
A10: 2026-09-20 | B10: Sun | C10: Client | D10: Dalo | E10: 1 | F10: OFF
A11: 2026-09-20 | B11: Sun | C11: Client | D11: Dalo | E11: 2 | F11: OFF
A12: 2026-09-20 | B12: Sun | C12: Client | D12: Dalo | E12: 3 | F12: OFF
A13: 2026-09-20 | B13: Sun | C13: Client | D13: Dodam | E13: 1 | F13: 23:00-11:00 | G13: Cath Valdez | H13: Island of Dreams | I13: 0.0722
A14: 2026-09-20 | B14: Sun | C14: Client | D14: Dodam | E14: 2 | F14: 07:00-19:00
A15: 2026-09-20 | B15: Sun | C15: Client | D15: Dol | E15: 1 | F15: 24:00-08:00 | G15: Smarley | H15: Dragon Valley | I15: 0.1792
A16: 2026-09-20 | B16: Sun | C16: Client | D16: Dol | E16: 2 | F16: OFF
A17: 2026-09-20 | B17: Sun | C17: Client | D17: Doma | E17: 1 | F17: OFF
A18: 2026-09-20 | B18: Sun | C18: Client | D18: Doma | E18: 2 | F18: 21:00-09:00 | G18: Mark Anthony | H18: Ivory Tower | I18: 0.0236
A19: 2026-09-20 | B19: Sun | C19: Client | D19: Duga | E19: 1 | F19: 07:00-15:00
A20: 2026-09-20 | B20: Sun | C20: Client | D20: Elf | E20: 1 | F20: OFF
A21: 2026-09-20 | B21: Sun | C21: Client | D21: Geonbae | E21: 1 | F21: OFF
A22: 2026-09-20 | B22: Sun | C22: Client | D22: Geonbae | E22: 2 | F22: 23:00-07:00 | G22: Jheco | H22: Ivory Tower | I22: 0.0601
A23: 2026-09-20 | B23: Sun | C23: Client | D23: Goop | E23: 1 | F23: OFF
A24: 2026-09-20 | B24: Sun | C24: Client | D24: Heon | E24: 1 | F24: OFF | H24: Abandoned Land (Abyss) 6 ivory tower 2 | K24: E-Potion O | L24: 555 buff | M24: Shield, Armour O
A25: 2026-09-20 | B25: Sun | C25: Client | D25: Jjuni | E25: 1 | F25: OFF
A26: 2026-09-20 | B26: Sun | C26: Client | D26: Jjuni | E26: 2 | F26: OFF
A27: 2026-09-20 | B27: Sun | C27: Client | D27: Jjuni | E27: 3 | F27: OFF | H27: Ivory Tower
A28: 2026-09-20 | B28: Sun | C28: Client | D28: Jo | E28: 1 | F28: OFF
A29: 2026-09-20 | B29: Sun | C29: Client | D29: Lammy Queen | E29: 1 | F29: OFF
A30: 2026-09-20 | B30: Sun | C30: Client | D30: Lammy Queen | E30: 2 | F30: 02:00-09:00 | G30: Richard Salupari | H30: Abandon Land | I30: 0.0387
A31: 2026-09-20 | B31: Sun | C31: Client | D31: Lolly | E31: 1 | F31: 07:00-15:00 | G31: Mitchell | H31: abandoned land 3 a land of corruption5 | K31: E-Potion O | L31: 555 buff | M31: Shield, Armour O
A32: 2026-09-20 | B32: Sun | C32: Client | D32: Mukkbo | E32: 1 | F32: OFF
A33: 2026-09-20 | B33: Sun | C33: Client | D33: Mukkbo | E33: 2 | F33: OFF
A34: 2026-09-20 | B34: Sun | C34: Client | D34: Munjin | E34: 1 | F34: OFF
A35: 2026-09-20 | B35: Sun | C35: Client | D35: Neburegi | E35: 1 | F35: OFF
A36: 2026-09-20 | B36: Sun | C36: Client | D36: Olleh | E36: 1 | F36: OFF
A37: 2026-09-20 | B37: Sun | C37: Client | D37: Olleh | E37: 2 | F37: OFF | H37: Ivory Tower
A38: 2026-09-20 | B38: Sun | C38: Client | D38: Perez | E38: 1 | F38: 08:00-16:00 | G38: Samantha
A39: 2026-09-20 | B39: Sun | C39: Client | D39: Perez | E39: 2 | F39: 13:00-18:00 | G39: Jel RIck | H39: IVORY TOWER / PEREZ | I39: 0.0073 | J39: 1600 | K39: 0 | L39: 0 | M39: 0
A40: 2026-09-20 | B40: Sun | C40: Client | D40: Perez | E40: 3 | F40: 21:00-05:00 | G40: Zenron | H40: Abandon Land | I40: 0.0112
...

Sheet Accounts
A1: Account | B1: Type | C1: Class | D1: Server | E1: KoreanName | F1: Aliases | G1: Customer | H1: SalesRep | I1: Status | J1: StartDate | K1: Notes
A2: ADA | B2: Client | C2: Knight | F2: ADA (Knight)|ADA-Knight|Ada | I2: Active
A3: Alex | B3: Client | C3: Knight | D3: 아툰 | F3: Alex Acc 31 Lv|Alex-Knight | I3: Active
A4: Beongaebul | B4: Client | I4: Active
A5: Captain | B5: Client | C5: Prince | F5: Captain - Lord (Prince)|Lord - Prince|Lord Prince | I5: Active
A6: Dalo | B6: Client | C6: Knight | F6: Dal-o|Dal-o-Knight|Dalo-Knight | I6: Active
A7: Dodam | B7: Client | C7: Elf | F7: Dodam-Elf | I7: Active
A8: Dol | B8: Client | C8: Knight | F8: Dol-Knight | I8: Active
A9: Doma | B9: Client | C9: Knight | F9: Doma-Knight | I9: Active
A10: Duga | B10: Client | C10: Knight | F10: Duga - Knight|Duga-Knight | I10: Active
A11: Elf | B11: Client | C11: Elf | F11: Elf-Elf | I11: Active
A12: Geonbae | B12: Client | C12: Elf | F12: Geonbae-Elf | I12: Active
A13: Goop | B13: Client | C13: Wizard | F13: Goop - Wizard | I13: Active
A14: Heon | B14: Client | C14: Knight | F14: Heon-Knight | I14: Active
A15: Jjuni | B15: Client | C15: Knight | F15: Jjuni-Knight | I15: Active
A16: Jo | B16: Client | C16: Elf | F16: Jo-Fairy | I16: Active
... A22: Olleh | B22: Client | C22: Knight | F22: Olleh-Knight|Olleh-knight | I22: Active
A23: Perez | B23: Client | D23: 아툰 | E23: 베레스 | F23: Perez-Spatoy|Spatoy | I23: Active
A24: Power20 | B24: Client | C24: Knight | D24: 아툰 | E24: 세상과짱뜬다 | F24: Power|Power20 33Lv|Power20-Knight | I24: Active
A25: Real Madrid | B25: Client | C25: Knight | F25: Real Madrid-Knight|Realmadrid | I25: Active
A26: Return | B26: Client | C26: Knight | F26: Return-Knight | I26: Active
A27: Road | B27: Client | F27: Road- Best Players Only|Road- Best Players Only! | I27: Active
A28: SSEN | B28: Client | F28: Ssen | I28: Active
A29: Tiger | B29: Client | C29: Knight | F29: Tiger-Knight | I29: Active
A30: Yeoseo | B30: Client | C30: Elf | F30: yeoseo-elf | I30: Active
A31: Zombie | B31: Client | C31: Knight | F31: Zombie(warrior)|Zombie-Knight | I31: Active
A32: Bang | B32: Client | C32: Wizard | F32: Bang-Wizard|Bang-Wizzard | I32: Inactive
A33: Bing | B33: Client | F33: Bing (Linpower40)|Linpower40 | I33: Inactive
A34: Bob | B34: Client | I34: Inactive
A35: Catleya | B35: Client | I35: Inactive
A36: Cheer Captain | B36: Client | F36: Cheer Captain (Leedy)|Leedy | I36: Inactive
A37: Eastin | B37: Client | I37: Inactive
A38: Gus | B38: Client | F38: CHUN 1|gus (CHUN 1) | I38: Inactive
A39: Hockey | B39: Client | C39: Elf | F39: Hockey-Elf | I39: Inactive
A40: Jangbi | B40: Client | C40: Knight | F40: Jangbi-Knight | I40: Inactive
A41: Jejo | B41: Client | C41: Knight | F41: Jejo-Knight | I41: Inactive
A42: Ji-Hyun | B42: Client | C42: Elf | F42: Ji-Hyun-Elf|Jihyun | I42: Inactive
A43: Kaisel | B43: Client | I43: Inactive
A44: League | B44: Client | C44: Knight | F44: League-Knight | I44: Inactive
A45: Linclassicterry | B45: Client | D45: 로엔그린 | E45: 제육 | I45: Inactive
...

Sheet Glossary
A1: Term | B1: Variants | C1: KoreanFull | D1: English | E1: Category | F1: Verified
A2: 바람방 | B2: 바람 방|바람의방 | C2: 바람방 | D2: Windroom | E2: hunting_ground | F2: Y
A3: 상아탑 | B3: 상탑|상아탑 N층 | C3: 상아탑 | D3: Ivory Tower (floor N = N층) | E3: hunting_ground | F3: Y
A4: 버땅 | B4: 버림받은땅|버림받은 땅 | C4: 버림받은 땅 | D4: Forsaken Land (버땅) | E4: hunting_ground | F4: N
A5: 버땅심연 | B5: 버땅 심연|심연 | C5: 버림받은 땅 심연 | D5: Forsaken Land – Abyss | E5: hunting_ground | F5: N
A6: 잊섬 | B6: 잊혀진섬|잊혀진 섬 | C6: 잊혀진 섬 | D6: Forgotten Island | E6: hunting_ground | F6: N
A7: 개미굴 | B7: 개미|ant | C7: 개미굴 | D7: Ant Cave (ant) | E7: hunting_ground | F7: N
A8: 몰이 | B8: 몰이사냥 | C8: 몰이 사냥 | D8: mob luring / pulling | E8: action | F8: Y
A9: 고정 | C9: 사냥터 고정 | D9: stay fixed at (one hunting ground) | E9: action | F9: Y
A10: 왓다갓다 | B10: 왔다갔다|왔다 갔다|번갈아 | C10: 번갈아 이동 | D10: alternate between | E10: action | F10: Y
A11: 두타임 | B11: 두 타임|2타임 | C11: 2개 시프트 | D11: both shifts (2 shifts) | E11: schedule | F11: Y
A12: 한타임 | B12: 한 타임|1타임 | C12: 1개 시프트 | D12: one shift | E12: schedule | F12: Y
A13: 점검 | B13: 서버점검 | C13: 서버 점검 | D13: server maintenance | E13: schedule | F13: Y
A14: 삭제 | B14: 취소 | C14: 시프트 삭제 | D14: cancel / remove shift | E14: schedule | F14: Y
A15: 추가 | C15: 시프트 추가 | D15: add extra shift | E15: schedule | F15: Y
A16: 경치 | B16: 경험치|경험 | C16: 경험치 | D16: EXP | E16: stat | F16: Y
A17: 카오 | B17: 카오틱 | C17: 카오틱 상태 | D17: chaotic (PK) status | E17: status | F17: Y
A18: 껐습니다 | B18: 껐어요|종료|나왔어요|미리 나왔어요|접종 | C18: 접속 종료 | D18: logged out (character is free to log in) | E18: status | F18: Y
A19: 밀어냈어 | B19: 밀렸어|튕김|튕겼어 | C19: 접속 끊김 | D19: got kicked / disconnected | E19: status | F19: Y
A20: 재접 | B20: 재로그인|다시 로그인 | C20: 다시 로그인 | D20: re-login | E20: action | F20: Y
A21: 혈원 | B21: 혈맹원 | C21: 혈맹원 | D21: clan member | E21: people | F21: Y
A22: 육성 | B22: 육성친구|대리 | C22: 대리 육성 담당자 | D22: booster / leveling trainer | E22: people | F22: Y
A23: 군주 | B23: 프린스 | C23: 군주 | D23: Prince (class) | E23: class | F23: Y
A24: 데나 | B24: 데스나이트|드가 | C24: 데스나이트 | D24: Death Knight (class) | E24: class | F24: Y
A25: 기사 | B25: 나이트 | C25: 기사 | D25: Knight (class) | E25: class | F25: Y
A26: 요정 | B26: 엘프 | C26: 요정 | D26: Elf (class) | E26: class | F26: Y
A27: 법사 | B27: 마법사|위자드 | C27: 마법사 | D27: Wizard (class) | E27: class | F27: Y
A28: GY | B28: 그야|그레이브야드|새벽 | C28: 24:00-08:00 시프트 | D28: graveyard shift (24:00-08:00) | E28: schedule | F28: Y
A29: 지피방 | C29: (확인 필요) | D29: (unknown — verify) | E29: unknown | F29: N

Sheet EventLog
A1: Timestamp | B1: Type | C1: Character | D1: Summary | E1: Status | F1: Answer

Sheet TL Schedule
A1: Date | B1: Day | C1: Leader | D1: Shift | E1: Attendance | F1: Note | G1: Week | H1: Key | I1: Display | J1: Hours | K1: Pay Week
A2: 2026-04-12 | B2: Sun | C2: ATL Jezryl | D2: OFF | G2: =ARRAYFORMULA(IF(A2:A50000="",,TEXT(IF(ISNUMBER(A2:A50000),A2:A50000,IFERROR(DATEVALUE(A2:A50000)))-WEEKDAY(IF(ISNUMBER(A2:A50000),A2:A50000,IFERROR(DATEVALUE(A2:A50000))))+1,"yyyy-mm-dd"))) | H2: =ARRAYFORMULA(IF(A2:A50000="",,TEXT(IF(ISNUMBER(A2:A50000),A2:A50000,IFERROR(DATEVALUE(A2:A50000))),"yyyy-mm-dd")&"|"&C2:C50000)) | I2: =ARRAYFORMULA(IF(A2:A50000="",,D2:D50000&IF(E2:E50000="","",CHAR(10)&E2:E50000))) | J2: =ARRAYFORMULA(IF(A2:A50000="",,IF((REGEXMATCH(D2:D50000,"^\s*\d{1,2}(:\d\d)?\s*[aApP][mM]\s*-\s*\d{1,2}(:\d\d)?\s*[aApP][mM]")=FALSE)+(LOWER(E2:E50000)="absent"),0,IFERROR(MOD((MOD(VALUE(REGEXEXTRACT(D2:D50000,"-\s*(\d{1,2})")),12)+12*REGEXMATCH(D2:D50000,"-\s*\d{1,2}(:\d\d)?\s*[pP][mM]"))-(MOD(VALUE(REGEXEXTRACT(D2:D50000,"^\s*(\d{1,2})")),12)+12*REGEXMATCH(D2:D50000,"^\s*\d{1,2}(:\d\d)?\s*[pP][mM]")),24),0)))) | K2: =ARRAYFORMULA(IF(A2:A50000="",,TEXT(IF(ISNUMBER(A2:A50000),A2:A50000,IFERROR(DATEVALUE(A2:A50000)))-WEEKDAY(IF(ISNUMBER(A2:A50000),A2:A50000,IFERROR(DATEVALUE(A2:A50000))),3),"yyyy-mm-dd")))
A3: 2026-04-12 | B3: Sun | C3: ATL Richard | D3: OFF
A4: 2026-04-12 | B4: Sun | C4: Alyssa | D4: Cancelled Off | E4: Present
A5: 2026-04-12 | B5: Sun | C5: Harley | D5: 12am-8am | E5: Present
A6: 2026-04-12 | B6: Sun | C6: Patrick | D6: 8am-4pm | E6: Present
A7: 2026-04-13 | B7: Mon | C7: ATL Jezryl | D7: OFF
A8: 2026-04-13 | B8: Mon | C8: ATL Richard | D8: OFF
A9: 2026-04-13 | B9: Mon | C9: Alyssa | D9: 4pm-12am | E9: Present
A10: 2026-04-13 | B10: Mon | C10: Harley | D10: 12am-8am | E10: Present
A11: 2026-04-13 | B11: Mon | C11: Patrick | D11: 8am-4pm | E11: Present
A12: 2026-04-14 | B12: Tue | C12: ATL Jezryl | D12: 8am-4pm | E12: Present
A13: 2026-04-14 | B13: Tue | C13: ATL Richard | D13: 12am-8am | E13: Present
A14: 2026-04-14 | B14: Tue | C14: Alyssa | D14: 4pm-12am | E14: Present
A15: 2026-04-14 | B15: Tue | C15: Harley | D15: 10pm-4am | E15: Present
A16: 2026-04-14 | B16: Tue | C16: Patrick | D16: 8am-4pm | E16: Present
A17: 2026-04-15 | B17: Wed | C17: ATL Jezryl | D17: 8am-4pm | E17: Present
A18: 2026-04-15 | B18: Wed | C18: ATL Richard | D18: 12am-8am | E18: Present
A19: 2026-04-15 | B19: Wed | C19: Alyssa | D19: OFF
A20: 2026-04-15 | B20: Wed | C20: Harley | D20: OFF
A21: 2026-04-15 | B21: Wed | C21: Patrick | D21: 8am-4pm | E21: Present
A22: 2026-04-16 | B22: Thu | C22: ATL Jezryl | D22: 8am-4pm | E22: Present
A23: 2026-04-16 | B23: Thu | C23: ATL Richard | D23: 12am-8am | E23: Present
A24: 2026-04-16 | B24: Thu | C24: Alyssa | D24: 4pm-12am | E24: Present
A25: 2026-04-16 | B25: Thu | C25: Harley | D25: 12am-8am | E25: Present
A26: 2026-04-16 | B26: Thu | C26: Patrick | D26: OFF
A27: 2026-04-17 | B27: Fri | C27: ATL Jezryl | D27: 8am-4pm | E27: Present
A28: 2026-04-17 | B28: Fri | C28: ATL Richard | D28: 12am-8am | E28: Present
A29: 2026-04-17 | B29: Fri | C29: Alyssa | D29: 4pm-12am | E29: Present
A30: 2026-04-17 | B30: Fri | C30: Harley | D30: 12am-8am | E30: Present
A31: 2026-04-17 | B31: Fri | C31: Patrick | D31: 8am-4pm | E31: Present
A32: 2026-04-18 | B32: Sat | C32: ATL Jezryl | D32: 8am-4pm | E32: Present
A33: 2026-04-18 | B33: Sat | C33: ATL Richard | D33: 12am-8am | E33: Present
A34: 2026-04-18 | B34: Sat | C34: Alyssa | D34: 4pm-12am | E34: Present
A35: 2026-04-18 | B35: Sat | C35: Harley | D35: OFF
A36: 2026-04-18 | B36: Sat | C36: Patrick | D36: OFF
A37: 2026-04-19 | B37: Sun | C37: ATL Jezryl | D37: OFF
A38: 2026-04-19 | B38: Sun | C38: ATL John Manuel | D38: 12am-8am | E38: Present
A39: 2026-04-19 | B39: Sun | C39: ATL Kent | D39: OFF
A40: 2026-04-19 | B40: Sun | C40: Alyssa | D40: CANCELLED OFF | E40: Present
...

Sheet Payroll
A1: PAYROLL — 2-week pay period (auto: Schedule + TL hours + OT − Death Penalty, Incentives)
A2: Period (Mon): | B2: =TEXT(DATEVALUE($G$2)+14*FLOOR((TODAY()-DATEVALUE($G$2))/14),"yyyy-mm-dd") | C2: =TEXT(DATEVALUE($B$2)+7,"yyyy-mm-dd") | D2: =TEXT(DATEVALUE($B$2)+13,"yyyy-mm-dd") | F2: Anchor: | G2: 2026-09-07 | H2: ← B2 = pay period start (a Monday; default = current period). Pay period = 2 weeks, Mon–Sun. C2 = week 2 start, D2 = period end, G2 = anchor Monday of any pay period.
A3: Payable Hrs = Base(플레이어 시프트 + TL 근무) + OT − Death Penalty. Incentives = Incentives 탭 금액 합계 (매니저 입력).
A4: Staff | B4: Week 1 Hrs | C4: Week 2 Hrs | D4: Base Hrs | E4: OT Hrs | F4: Penalty Hrs | G4: Payable Hrs | H4: Incentives | I4: Shifts | J4: Characters
A5: Adrian Torres | B5: =IF($A5="","",SUMIFS(Schedule!$P:$P,Schedule!$G:$G,$A5,Schedule!$U:$U,$B$2)+SUMIFS('TL Schedule'!$J:$J,'TL Schedule'!$C:$C,$A5,'TL Schedule'!$K:$K,$B$2)) | C5: =IF($A5="","",SUMIFS(Schedule!$P:$P,Schedule!$G:$G,$A5,Schedule!$U:$U,$C$2)+SUMIFS('TL Schedule'!$J:$J,'TL Schedule'!$C:$C,$A5,'TL Schedule'!$K:$K,$C$2)) | D5: =IF($A5="","",B5+C5) | E5: =IF($A5="","",SUMIFS(Overtime!$H:$H,Overtime!$B:$B,$A5,Overtime!$N:$N,$B$2)+SUMIFS(Overtime!$H:$H,Overtime!$B:$B,$A5,Overtime!$N:$N,$C$2)) | F5: =IF($A5="","",SUMIFS('Death Penalty'!$E:$E,'Death Penalty'!$B:$B,$A5,'Death Penalty'!$L:$L,$B$2)+SUMIFS('Death Penalty'!$E:$E,'Death Penalty'!$B:$B,$A5,'Death Penalty'!$L:$L,$C$2)) | G5: =IF($A5="","",D5+E5-F5) | H5: =IF($A5="","",SUMIFS(Incentives!$H:$H,Incentives!$B:$B,$A5,Incentives!$N:$N,$B$2)+SUMIFS(Incentives!$H:$H,Incentives!$B:$B,$A5,Incentives!$N:$N,$C$2)) | I5: =IF($A5="","",COUNTIFS(Schedule!$G:$G,$A5,Schedule!$U:$U,$B$2,Schedule!$P:$P,">0")+COUNTIFS('TL Schedule'!$C:$C,$A5,'TL Schedule'!$K:$K,$B$2,'TL Schedule'!$J:$J,">0")+COUNTIFS(Schedule!$G:$G,$A5,Schedule!$U:$U,$C$2,Schedule!$P:$P,">0")+COUNTIFS('TL Schedule'!$C:$C,$A5,'TL Schedule'!$K:$K,$C$2,'TL Schedule'!$J:$J,">0")) | J5: =IF($A5="","",IFERROR(TEXTJOIN(", ",TRUE,UNIQUE(FILTER(Schedule!$D$2:$D50000,Schedule!$G$2:$G50000=$A5,Schedule!$P$2:$P50000>0,((Schedule!$U$2:$U50000=$B$2)+(Schedule!$U$2:$U50000=$C$2))))),""))
A6: Alyssa | B6: =IF($A6="","",SUMIFS(Schedule!$P:$P,Schedule!$G:$G,$A6,Schedule!$U:$U,$B$2)+SUMIFS('TL Schedule'!$J:$J,'TL Schedule'!$C:$C,$A6,'TL Schedule'!$K:$K,$B$2)) | C6: =IF($A6="","",SUMIFS(Schedule!$P:$P,Schedule!$G:$G,$A6,Schedule!$U:$U,$C$2)+SUMIFS('TL Schedule'!$J:$J,'TL Schedule'!$C:$C,$A6,'TL Schedule'!$K:$K,$C$2)) | D6: =IF($A6="","",B6+C6) | E6: =IF($A6="","",SUMIFS(Overtime!$H:$H,Overtime!$B:$B,$A6,Overtime!$N:$N,$B$2)+SUMIFS(Overtime!$H:$H,Overtime!$B:$B,$A6,Overtime!$N:$N,$C$2)) | F6: =IF($A6="","",SUMIFS('Death Penalty'!$E:$E,'Death Penalty'!$B:$B,$A6,'Death Penalty'!$L:$L,$B$2)+SUMIFS('Death Penalty'!$E:$E,'Death Penalty'!$B:$B,$A6,'Death Penalty'!$L:$L,$C$2)) | G6: =IF($A6="","",D6+E6-F6) | H6: =IF($A6="","",SUMIFS(Incentives!$H:$H,Incentives!$B:$B,$A6,Incentives!$N:$N,$B$2)+SUMIFS(Incentives!$H:$H,Incentives!$B:$B,$A6,Incentives!$N:$N,$C$2)) | I6: =IF($A6="","",COUNTIFS(Schedule!$G:$G,$A6,Schedule!$U:$U,$B$2,Schedule!$P:$P,">0")+COUNTIFS('TL Schedule'!$C:$C,$A6,'TL Schedule'!$K:$K,$B$2,'TL Schedule'!$J:$J,">0")+COUNTIFS(Schedule!$G:$G,$A6,Schedule!$U:$U,$C$2,Schedule!$P:$P,">0")+COUNTIFS('TL Schedule'!$C:$C,$A6,'TL Schedule'!$K:$K,$C$2,'TL Schedule'!$J:$J,">0")) | J6: =IF($A6="","",IFERROR(TEXTJOIN(", ",TRUE,UNIQUE(FILTER(Schedule!$D$2:$D50000,Schedule!$G$2:$G50000=$A6,Schedule!$P$2:$P50000>0,((Schedule!$U$2:$U50000=$B$2)+(Schedule!$U$2:$U50000=$C$2))))),""))
A7: Angelo Diocales | B7: =IF($A7="","",SUMIFS(Schedule!$P:$P,Schedule!$G:$G,$A7,Schedule!$U:$U,$B$2)+SUMIFS('TL Schedule'!$J:$J,'TL Schedule'!$C:$C,$A7,'TL Schedule'!$K:$K,$B$2)) | C7: =IF($A7="","",SUMIFS(Schedule!$P:$P,Schedule!$G:$G,$A7,Schedule!$U:$U,$C$2)+SUMIFS('TL Schedule'!$J:$J,'TL Schedule'!$C:$C,$A7,'TL Schedule'!$K:$K,$C$2)) | D7: =IF($A7="","",B7+C7) | E7: =IF($A7="","",SUMIFS(Overtime!$H:$H,Overtime!$B:$B,$A7,Overtime!$N:$N,$B$2)+SUMIFS(Overtime!$H:$H,Overtime!$B:$B,$A7,Overtime!$N:$N,$C$2)) | F7: =IF($A7="","",SUMIFS('Death Penalty'!$E:$E,'Death Penalty'!$B:$B,$A7,'Death Penalty'!$L:$L,$B$2)+SUMIFS('Death Penalty'!$E:$E,'Death Penalty'!$B:$B,$A7,'Death Penalty'!$L:$L,$C$2)) | G7: =IF($A7="","",D7+E7-F7) | H7: =IF($A7="","",SUMIFS(Incentives!$H:$H,Incentives!$B:$B,$A7,Incentives!$N:$N,$B$2)+SUMIFS(Incentives!$H:$H,Incentives!$B:$B,$A7,Incentives!$N:$N,$C$2)) | I7: =IF($A7="","",COUNTIFS(Schedule!$G:$G,$A7,Schedule!$U:$U,$B$2,Schedule!$P:$P,">0")+COUNTIFS('TL Schedule'!$C:$C,$A7,'TL Schedule'!$K:$K,$B$2,'TL Schedule'!$J:$J,">0")+COUNTIFS(Schedule!$G:$G,$A7,Schedule!$U:$U,$C$2,Schedule!$P:$P,">0")+COUNTIFS('TL Schedule'!$C:$C,$A7,'TL Schedule'!$K:$K,$C$2,'TL Schedule'!$J:$J,">0")) | J7: =IF($A7="","",IFERROR(TEXTJOIN(", ",TRUE,UNIQUE(FILTER(Schedule!$D$2:$D50000,Schedule!$G$2:$G50000=$A7,Schedule!$P$2:$P50000>0,((Schedule!$U$2:$U50000=$B$2)+(Schedule!$U$2:$U50000=$C$2))))),""))
A8: Cath Valdez | B8: =IF($A8="","",SUMIFS(Schedule!$P:$P,Schedule!$G:$G,$A8,Schedule!$U:$U,$B$2)+SUMIFS('TL Schedule'!$J:$J,'TL Schedule'!$C:$C,$A8,'TL Schedule'!$K:$K,$B$2)) | C8: =IF($A8="","",SUMIFS(Schedule!$P:$P,Schedule!$G:$G,$A8,Schedule!$U:$U,$C$2)+SUMIFS('TL Schedule'!$J:$J,'TL Schedule'!$C:$C,$A8,'TL Schedule'!$K:$K,$C$2)) | D8: =IF($A8="","",B8+C8) | E8: =IF($A8="","",SUMIFS(Overtime!$H:$H,Overtime!$B:$B,$A8,Overtime!$N:$N,$B$2)+SUMIFS(Overtime!$H:$H,Overtime!$B:$B,$A8,Overtime!$N:$N,$C$2)) | F8: =IF($A8="","",SUMIFS('Death Penalty'!$E:$E,'Death Penalty'!$B:$B,$A8,'Death Penalty'!$L:$L,$B$2)+SUMIFS('Death Penalty'!$E:$E,'Death Penalty'!$B:$B,$A8,'Death Penalty'!$L:$L,$C$2)) | G8: =IF($A8="","",D8+E8-F8) | H8: =IF($A8="","",SUMIFS(Incentives!$H:$H,Incentives!$B:$B,$A8,Incentives!$N:$N,$B$2)+SUMIFS(Incentives!$H:$H,Incentives!$B:$B,$A8,Incentives!$N:$N,$C$2)) | I8: =IF($A8="","",COUNTIFS(Schedule!$G:$G,$A8,Schedule!$U:$U,$B$2,Schedule!$P:$P,">0")+COUNTIFS('TL Schedule'!$C:$C,$A8,'TL Schedule'!$K:$K,$B$2,'TL Schedule'!$J:$J,">0")+COUNTIFS(Schedule!$G:$G,$A8,Schedule!$U:$U,$C$2,Schedule!$P:$P,">0")+COUNTIFS('TL Schedule'!$C:$C,$A8,'TL Schedule'!$K:$K,$C$2,'TL Schedule'!$J:$J,">0")) | J8: =IF($A8="","",IFERROR(TEXTJOIN(", ",TRUE,UNIQUE(FILTER(Schedule!$D$2:$D50000,Schedule!$G$2:$G50000=$A8,Schedule!$P$2:$P50000>0,((Schedule!$U$2:$U50000=$B$2)+(Schedule!$U$2:$U50000=$C$2))))),""))
A9: Cejay | B9: =IF($A9="","",SUMIFS(Schedule!$P:$P,Schedule!$G:$G,$A9,Schedule!$U:$U,$B$2)+SUMIFS('TL Schedule'!$J:$J,'TL Schedule'!$C:$C,$A9,'TL Schedule'!$K:$K,$B$2)) | C9: =IF($A9="","",SUMIFS(Schedule!$P:$P,Schedule!$G:$G,$A9,Schedule!$U:$U,$C$2)+SUMIFS('TL Schedule'!$J:$J,'TL Schedule'!$C:$C,$A9,'TL Schedule'!$K:$K,$C$2)) | D9: =IF($A9="","",B9+C9) | E9: =IF($A9="","",SUMIFS(Overtime!$H:$H,Overtime!$B:$B,$A9,Overtime!$N:$N,$B$2)+SUMIFS(Overtime!$H:$H,Overtime!$B:$B,$A9,Overtime!$N:$N,$C$2)) | F9: =IF($A9="","",SUMIFS('Death Penalty'!$E:$E,'Death Penalty'!$B:$B,$A9,'Death Penalty'!$L:$L,$B$2)+SUMIFS('Death Penalty'!$E:$E,'Death Penalty'!$B:$B,$A9,'Death Penalty'!$L:$L,$C$2)) | G9: =IF($A9="","",D9+E9-F9) | H9: =IF($A9="","",SUMIFS(Incentives!$H:$H,Incentives!$B:$B,$A9,Incentives!$N:$N,$B$2)+SUMIFS(Incentives!$H:$H,Incentives!$B:$B,$A9,Incentives!$N:$N,$C$2)) | I9: =IF($A9="","",COUNTIFS(Schedule!$G:$G,$A9,Schedule!$U:$U,$B$2,Schedule!$P:$P,">0")+COUNTIFS('TL Schedule'!$C:$C,$A9,'TL Schedule'!$K:$K,$B$2,'TL Schedule'!$J:$J,">0")+COUNTIFS(Schedule!$G:$G,$A9,Schedule!$U:$U,$C$2,Schedule!$P:$P,">0")+COUNTIFS('TL Schedule'!$C:$C,$A9,'TL Schedule'!$K:$K,$C$2,'TL Schedule'!$J:$J,">0")) | J9: =IF($A9="","",IFERROR(TEXTJOIN(", ",TRUE,UNIQUE(FILTER(Schedule!$D$2:$D50000,Schedule!$G$2:$G50000=$A9,Schedule!$P$2:$P50000>0,((Schedule!$U$2:$U50000=$B$2)+(Schedule!$U$2:$U50000=$C$2))))),""))
A10: Charles Bernades | B10: =IF($A10="","",SUMIFS(Schedule!$P:$P,Schedule!$G:$G,$A10,Schedule!$U:$U,$B$2)+SUMIFS('TL Schedule'!$J:$J,'TL Schedule'!$C:$C,$A10,'TL Schedule'!$K:$K,$B$2)) | C10: =IF($A10="","",SUMIFS(Schedule!$P:$P,Schedule!$G:$G,$A10,Schedule!$U:$U,$C$2)+SUMIFS('TL Schedule'!$J:$J,'TL Schedule'!$C:$C,$A10,'TL Schedule'!$K:$K,$C$2)) | D10: =IF($A10="","",B10+C10) | E10: =IF($A10="","",SUMIFS(Overtime!$H:$H,Overtime!$B:$B,$A10,Overtime!$N:$N,$B$2)+SUMIFS(Overtime!$H:$H,Overtime!$B:$B,$A10,Overtime!$N:$N,$C$2)) | F10: =IF($A10="","",SUMIFS('Death Penalty'!$E:$E,'Death Penalty'!$B:$B,$A10,'Death Penalty'!$L:$L,$B$2)+SUMIFS('Death Penalty'!$E:$E,'Death Penalty'!$B:$B,$A10,'Death Penalty'!$L:$L,$C$2)) | G10: =IF($A10="","",D10+E10-F10) | H10: =IF($A10="","",SUMIFS(Incentives!$H:$H,Incentives!$B:$B,$A10,Incentives!$N:$N,$B$2)+SUMIFS(Incentives!$H:$H,Incentives!$B:$B,$A10,Incentives!$N:$N,$C$2)) | I10: =IF($A10="","",COUNTIFS(Schedule!$G:$G,$A10,Schedule!$U:$U,$B$2,Schedule!$P:$P,">0")+COUNTIFS('TL Schedule'!$C:$C,$A10,'TL Schedule'!$K:$K,$B$2,'TL Schedule'!$J:$J,">0")+COUNTIFS(Schedule!$G:$G,$A10,Schedule!$U:$U,$C$2,Schedule!$P:$P,">0")+COUNTIFS('TL Schedule'!$C:$C,$A10,'TL Schedule'!$K:$K,$C$2,'TL Schedule'!$J:$J,">0")) | J10: =IF($A10="","",IFERROR(TEXTJOIN(", ",TRUE,UNIQUE(FILTER(Schedule!$D$2:$D50000,Schedule!$G$2:$G50000=$A10,Schedule!$P$2:$P50000>0,((Schedule!$U$2:$U50000=$B$2)+(Schedule!$U$2:$U50000=$C$2))))),""))
A11: Chester | B11: =IF($A11="","",SUMIFS(Schedule!$P:$P,Schedule!$G:$G,$A11,Schedule!$U:$U,$B$2)+SUMIFS('TL Schedule'!$J:$J,'TL Schedule'!$C:$C,$A11,'TL Schedule'!$K:$K,$B$2)) | C11: =IF($A11="","",SUMIFS(Schedule!$P:$P,Schedule!$G:$G,$A11,Schedule!$U:$U,$C$2)+SUMIFS('TL Schedule'!$J:$J,'TL Schedule'!$C:$C,$A11,'TL Schedule'!$K:$K,$C$2)) | D11: =IF($A11="","",B11+C11) | E11: =IF($A11="","",SUMIFS(Overtime!$H:$H,Overtime!$B:$B,$A11,Overtime!$N:$N,$B$2)+SUMIFS(Overtime!$H:$H,Overtime!$B:$B,$A11,Overtime!$N:$N,$C$2)) | F11: =IF($A11="","",SUMIFS('Death Penalty'!$E:$E,'Death Penalty'!$B:$B,$A11,'Death Penalty'!$L:$L,$B$2)+SUMIFS('Death Penalty'!$E:$E,'Death Penalty'!$B:$B,$A11,'Death Penalty'!$L:$L,$C$2)) | G11: =IF($A11="","",D11+E11-F11) | H11: =IF($A11="","",SUMIFS(Incentives!$H:$H,Incentives!$B:$B,$A11,Incentives!$N:$N,$B$2)+SUMIFS(Incentives!$H:$H,Incentives!$B:$B,$A11,Incentives!$N:$N,$C$2)) | I11: =IF($A11="","",COUNTIFS(Schedule!$G:$G,$A11,Schedule!$U:$U,$B$2,Schedule!$P:$P,">0")+COUNTIFS('TL Schedule'!$C:$C,$A11,'TL Schedule'!$K:$K,$B$2,'TL Schedule'!$J:$J,">0")+COUNTIFS(Schedule!$G:$G,$A11,Schedule!$U:$U,$C$2,Schedule!$P:$P,">0")+COUNTIFS('TL Schedule'!$C:$C,$A11,'TL Schedule'!$K:$K,$C$2,'TL Schedule'!$J:$J,">0")) | J11: =IF($A11="","",IFERROR(TEXTJOIN(", ",TRUE,UNIQUE(FILTER(Schedule!$D$2:$D50000,Schedule!$G$2:$G50000=$A11,Schedule!$P$2:$P50000>0,((Schedule!$U$2:$U50000=$B$2)+(Schedule!$U$2:$U50000=$C$2))))),""))
A12: Christelle | B12: =IF($A12="","",SUMIFS(Schedule!$P:$P,Schedule!$G:$G,$A12,Schedule!$U:$U,$B$2)+SUMIFS('TL Schedule'!$J:$J,'TL Schedule'!$C:$C,$A12,'TL Schedule'!$K:$K,$B$2)) | C12: =IF($A12="","",SUMIFS(Schedule!$P:$P,Schedule!$G:$G,$A12,Schedule!$U:$U,$C$2)+SUMIFS('TL Schedule'!$J:$J,'TL Schedule'!$C:$C,$A12,'TL Schedule'!$K:$K,$C$2)) | D12: =IF($A12="","",B12+C12) | E12: =IF($A12="","",SUMIFS(Overtime!$H:$H,Overtime!$B:$B,$A12,Overtime!$N:$N,$B$2)+SUMIFS(Overtime!$H:$H,Overtime!$B:$B,$A12,Overtime!$N:$N,$C$2)) | F12: =IF($A12="","",SUMIFS('Death Penalty'!$E:$E,'Death Penalty'!$B:$B,$A12,'Death Penalty'!$L:$L,$B$2)+SUMIFS('Death Penalty'!$E:$E,'Death Penalty'!$B:$B,$A12,'Death Penalty'!$L:$L,$C$2)) | G12: =IF($A12="","",D12+E12-F12) | H12: =IF($A12="","",SUMIFS(Incentives!$H:$H,Incentives!$B:$B,$A12,Incentives!$N:$N,$B$2)+SUMIFS(Incentives!$H:$H,Incentives!$B:$B,$A12,Incentives!$N:$N,$C$2)) | I12: =IF($A12="","",COUNTIFS(Schedule!$G:$G,$A12,Schedule!$U:$U,$B$2,Schedule!$P:$P,">0")+COUNTIFS('TL Schedule'!$C:$C,$A12,'TL Schedule'!$K:$K,$B$2,'TL Schedule'!$J:$J,">0")+COUNTIFS(Schedule!$G:$G,$A12,Schedule!$U:$U,$C$2,Schedule!$P:$P,">0")+COUNTIFS('TL Schedule'!$C:$C,$A12,'TL Schedule'!$K:$K,$C$2,'TL Schedule'!$J:$J,">0")) | J12: =IF($A12="","",IFERROR(TEXTJOIN(", ",TRUE,UNIQUE(FILTER(Schedule!$D$2:$D50000,Schedule!$G$2:$G50000=$A12,Schedule!$P$2:$P50000>0,((Schedule!$U$2:$U50000=$B$2)+(Schedule!$U$2:$U50000=$C$2))))),""))
A13: David Ayag | B13: =IF($A13="","",SUMIFS(Schedule!$P:$P,Schedule!$G:$G,$A13,Schedule!$U:$U,$B$2)+SUMIFS('TL Schedule'!$J:$J,'TL Schedule'!$C:$C,$A13,'TL Schedule'!$K:$K,$B$2)) | C13: =IF($A13="","",SUMIFS(Schedule!$P:$P,Schedule!$G:$G,$A13,Schedule!$U:$U,$C$2)+SUMIFS('TL Schedule'!$J:$J,'TL Schedule'!$C:$C,$A13,'TL Schedule'!$K:$K,$C$2)) | D13: =IF($A13="","",B13+C13) | E13: =IF($A13="","",SUMIFS(Overtime!$H:$H,Overtime!$B:$B,$A13,Overtime!$N:$N,$B$2)+SUMIFS(Overtime!$H:$H,Overtime!$B:$B,$A13,Overtime!$N:$N,$C$2)) | F13: =IF($A13="","",SUMIFS('Death Penalty'!$E:$E,'Death Penalty'!$B:$B,$A13,'Death Penalty'!$L:$L,$B$2)+SUMIFS('Death Penalty'!$E:$E,'Death Penalty'!$B:$B,$A13,'Death Penalty'!$L:$L,$C$2)) | G13: =IF($A13="","",D13+E13-F13) | H13: =IF($A13="","",SUMIFS(Incentives!$H:$H,Incentives!$B:$B,$A13,Incentives!$N:$N,$B$2)+SUMIFS(Incentives!$H:$H,Incentives!$B:$B,$A13,Incentives!$N:$N,$C$2)) | I13: =IF($A13="","",COUNTIFS(Schedule!$G:$G,$A13,Schedule!$U:$U,$B$2,Schedule!$P:$P,">0")+COUNTIFS('TL Schedule'!$C:$C,$A13,'TL Schedule'!$K:$K,$B$2,'TL Schedule'!$J:$J,">0")+COUNTIFS(Schedule!$G:$G,$A13,Schedule!$U:$U,$C$2,Schedule!$P:$P,">0")+COUNTIFS('TL Schedule'!$C:$C,$A13,'TL Schedule'!$K:$K,$C$2,'TL Schedule'!$J:$J,">0")) | J13: =IF($A13="","",IFERROR(TEXTJOIN(", ",TRUE,UNIQUE(FILTER(Schedule!$D$2:$D50000,Schedule!$G$2:$G50000=$A13,Schedule!$P$2:$P50000>0,((Schedule!$U$2:$U50000=$B$2)+(Schedule!$U$2:$U50000=$C$2))))),""))
A14: Ehder Lhen | B14: =IF($A14="","",SUMIFS(Schedule!$P:$P,Schedule!$G:$G,$A14,Schedule!$U:$U,$B$2)+SUMIFS('TL Schedule'!$J:$J,'TL Schedule'!$C:$C,$A14,'TL Schedule'!$K:$K,$B$2)) | C14: =IF($A14="","",SUMIFS(Schedule!$P:$P,Schedule!$G:$G,$A14,Schedule!$U:$U,$C$2)+SUMIFS('TL Schedule'!$J:$J,'TL Schedule'!$C:$C,$A14,'TL Schedule'!$K:$K,$C$2)) | D14: =IF($A14="","",B14+C14) | E14: =IF($A14="","",SUMIFS(Overtime!$H:$H,Overtime!$B:$B,$A14,Overtime!$N:$N,$B$2)+SUMIFS(Overtime!$H:$H,Overtime!$B:$B,$A14,Overtime!$N:$N,$C$2)) | F14: =IF($A14="","",SUMIFS('Death Penalty'!$E:$E,'Death Penalty'!$B:$B,$A14,'Death Penalty'!$L:$L,$B$2)+SUMIFS('Death Penalty'!$E:$E,'Death Penalty'!$B:$B,$A14,'Death Penalty'!$L:$L,$C$2)) | G14: =IF($A14="","",D14+E14-F14) | H14: =IF($A14="","",SUMIFS(Incentives!$H:$H,Incentives!$B:$B,$A14,Incentives!$N:$N,$B$2)+SUMIFS(Incentives!$H:$H,Incentives!$B:$B,$A14,Incentives!$N:$N,$C$2)) | I14: =IF($A14="","",COUNTIFS(Schedule!$G:$G,$A14,Schedule!$U:$U,$B$2,Schedule!$P:$P,">0")+COUNTIFS('TL Schedule'!$C:$C,$A14,'TL Schedule'!$K:$K,$B$2,'TL Schedule'!$J:$J,">0")+COUNTIFS(Schedule!$G:$G,$A14,Schedule!$U:$U,$C$2,Schedule!$P:$P,">0")+COUNTIFS('TL Schedule'!$C:$C,$A14,'TL Schedule'!$K:$K,$C$2,'TL Schedule'!$J:$J,">0")) | J14: =IF($A14="","",IFERROR(TEXTJOIN(", ",TRUE,UNIQUE(FILTER(Schedule!$D$2:$D50000,Schedule!$G$2:$G50000=$A14,Schedule!$P$2:$P50000>0,((Schedule!$U$2:$U50000=$B$2)+(Schedule!$U$2:$U50000=$C$2))))),""))
A15: Isiah | B15: =IF($A15="","",SUMIFS(Schedule!$P:$P,Schedule!$G:$G,$A15,Schedule!$U:$U,$B$2)+SUMIFS('TL Schedule'!$J:$J,'TL Schedule'!$C:$C,$A15,'TL Schedule'!$K:$K,$B$2)) | C15: =IF($A15="","",SUMIFS(Schedule!$P:$P,Schedule!$G:$G,$A15,Schedule!$U:$U,$C$2)+SUMIFS('TL Schedule'!$J:$J,'TL Schedule'!$C:$C,$A15,'TL Schedule'!$K:$K,$C$2)) | D15: =IF($A15="","",B15+C15) | E15: =IF($A15="","",SUMIFS(Overtime!$H:$H,Overtime!$B:$B,$A15,Overtime!$N:$N,$B$2)+SUMIFS(Overtime!$H:$H,Overtime!$B:$B,$A15,Overtime!$N:$N,$C$2)) | F15: =IF($A15="","",SUMIFS('Death Penalty'!$E:$E,'Death Penalty'!$B:$B,$A15,'Death Penalty'!$L:$L,$B$2)+SUMIFS('Death Penalty'!$E:$E,'Death Penalty'!$B:$B,$A15,'Death Penalty'!$L:$L,$C$2)) | G15: =IF($A15="","",D15+E15-F15) | H15: =IF($A15="","",SUMIFS(Incentives!$H:$H,Incentives!$B:$B,$A15,Incentives!$N:$N,$B$2)+SUMIFS(Incentives!$H:$H,Incentives!$B:$B,$A15,Incentives!$N:$N,$C$2)) | I15: =IF($A15="","",COUNTIFS(Schedule!$G:$G,$A15,Schedule!$U:$U,$B$2,Schedule!$P:$P,">0")+COUNTIFS('TL Schedule'!$C:$C,$A15,'TL Schedule'!$K:$K,$B$2,'TL Schedule'!$J:$J,">0")+COUNTIFS(Schedule!$G:$G,$A15,Schedule!$U:$U,$C$2,Schedule!$P:$P,">0")+COUNTIFS('TL Schedule'!$C:$C,$A15,'TL Schedule'!$K:$K,$C$2,'TL Schedule'!$J:$J,">0")) | J15: =IF($A15="","",IFERROR(TEXTJOIN(", ",TRUE,UNIQUE(FILTER(Schedule!$D$2:$D50000,Schedule!$G$2:$G50000=$A15,Schedule!$P$2:$P50000>0,((Schedule!$U$2:$U50000=$B$2)+(Schedule!$U$2:$U50000=$C$2))))),""))
A16: JM Racca | B16: =IF($A16="","",SUMIFS(Schedule!$P:$P,Schedule!$G:$G,$A16,Schedule!$U:$U,$B$2)+SUMIFS('TL Schedule'!$J:$J,'TL Schedule'!$C:$C,$A16,'TL Schedule'!$K:$K,$B$2)) | C16: =IF($A16="","",SUMIFS(Schedule!$P:$P,Schedule!$G:$G,$A16,Schedule!$U:$U,$C$2)+SUMIFS('TL Schedule'!$J:$J,'TL Schedule'!$C:$C,$A16,'TL Schedule'!$K:$K,$C$2)) | D16: =IF($A16="","",B16+C16) | E16: =IF($A16="","",SUMIFS(Overtime!$H:$H,Overtime!$B:$B,$A16,Overtime!$N:$N,$B$2)+SUMIFS(Overtime!$H:$H,Overtime!$B:$B,$A16,Overtime!$N:$N,$C$2)) | F16: =IF($A16="","",SUMIFS('Death Penalty'!$E:$E,'Death Penalty'!$B:$B,$A16,'Death Penalty'!$L:$L,$B$2)+SUMIFS('Death Penalty'!$E:$E,'Death Penalty'!$B:$B,$A16,'Death Penalty'!$L:$L,$C$2)) | G16: =IF($A16="","",D16+E16-F16) | H16: =IF($A16="","",SUMIFS(Incentives!$H:$H,Incentives!$B:$B,$A16,Incentives!$N:$N,$B$2)+SUMIFS(Incentives!$H:$H,Incentives!$B:$B,$A16,Incentives!$N:$N,$C$2)) | I16: =IF($A16="","",COUNTIFS(Schedule!$G:$G,$A16,Schedule!$U:$U,$B$2,Schedule!$P:$P,">0")+COUNTIFS('TL Schedule'!$C:$C,$A16,'TL Schedule'!$K:$K,$B$2,'TL Schedule'!$J:$J,">0")+COUNTIFS(Schedule!$G:$G,$A16,Schedule!$U:$U,$C$2,Schedule!$P:$P,">0")+COUNTIFS('TL Schedule'!$C:$C,$A16,'TL Schedule'!$K:$K,$C$2,'TL Schedule'!$J:$J,">0")) | J16: =IF($A16="","",IFERROR(TEXTJOIN(", ",TRUE,UNIQUE(FILTER(Schedule!$D$2:$D50000,Schedule!$G$2:$G50000=$A16,Schedule!$P$2:$P50000>0,((Schedule!$U$2:$U50000=$B$2)+(Schedule!$U$2:$U50000=$C$2))))),""))
A17: Jan Nino | B17: =IF($A17="","",SUMIFS(Schedule!$P:$P,Schedule!$G:$G,$A17,Schedule!$U:$U,$B$2)+SUMIFS('TL Schedule'!$J:$J,'TL Schedule'!$C:$C,$A17,'TL Schedule'!$K:$K,$B$2)) | C17: =IF($A17="","",SUMIFS(Schedule!$P:$P,Schedule!$G:$G,$A17,Schedule!$U:$U,$C$2)+SUMIFS('TL Schedule'!$J:$J,'TL Schedule'!$C:$C,$A17,'TL Schedule'!$K:$K,$C$2)) | D17: =IF($A17="","",B17+C17) | E17: =IF($A17="","",SUMIFS(Overtime!$H:$H,Overtime!$B:$B,$A17,Overtime!$N:$N,$B$2)+SUMIFS(Overtime!$H:$H,Overtime!$B:$B,$A17,Overtime!$N:$N,$C$2)) | F17: =IF($A17="","",SUMIFS('Death Penalty'!$E:$E,'Death Penalty'!$B:$B,$A17,'Death Penalty'!$L:$L,$B$2)+SUMIFS('Death Penalty'!$E:$E,'Death Penalty'!$B:$B,$A17,'Death Penalty'!$L:$L,$C$2)) | G17: =IF($A17="","",D17+E17-F17) | H17: =IF($A17="","",SUMIFS(Incentives!$H:$H,Incentives!$B:$B,$A17,Incentives!$N:$N,$B$2)+SUMIFS(Incentives!$H:$H,Incentives!$B:$B,$A17,Incentives!$N:$N,$C$2)) | I17: =IF($A17="","",COUNTIFS(Schedule!$G:$G,$A17,Schedule!$U:$U,$B$2,Schedule!$P:$P,">0")+COUNTIFS('TL Schedule'!$C:$C,$A17,'TL Schedule'!$K:$K,$B$2,'TL Schedule'!$J:$J,">0")+COUNTIFS(Schedule!$G:$G,$A17,Schedule!$U:$U,$C$2,Schedule!$P:$P,">0")+COUNTIFS('TL Schedule'!$C:$C,$A17,'TL Schedule'!$K:$K,$C$2,'TL Schedule'!$J:$J,">0")) | J17: =IF($A17="","",IFERROR(TEXTJOIN(", ",TRUE,UNIQUE(FILTER(Schedule!$D$2:$D50000,Schedule!$G$2:$G50000=$A17,Schedule!$P$2:$P50000>0,((Schedule!$U$2:$U50000=$B$2)+(Schedule!$U$2:$U50000=$C$2))))),""))
A18: Jay Penilla | B18: =IF($A18="","",SUMIFS(Schedule!$P:$P,Schedule!$G:$G,$A18,Schedule!$U:$U,$B$2)+SUMIFS('TL Schedule'!$J:$J,'TL Schedule'!$C:$C,$A18,'TL Schedule'!$K:$K,$B$2)) | C18: =IF($A18="","",SUMIFS(Schedule!$P:$P,Schedule!$G:$G,$A18,Schedule!$U:$U,$C$2)+SUMIFS('TL Schedule'!$J:$J,'TL Schedule'!$C:$C,$A18,'TL Schedule'!$K:$K,$C$2)) | D18: =IF($A18="","",B18+C18) | E18: =IF($A18="","",SUMIFS(Overtime!$H:$H,Overtime!$B:$B,$A18,Overtime!$N:$N,$B$2)+SUMIFS(Overtime!$H:$H,Overtime!$B:$B,$A18,Overtime!$N:$N,$C$2)) | F18: =IF($A18="","",SUMIFS('Death Penalty'!$E:$E,'Death Penalty'!$B:$B,$A18,'Death Penalty'!$L:$L,$B$2)+SUMIFS('Death Penalty'!$E:$E,'Death Penalty'!$B:$B,$A18,'Death Penalty'!$L:$L,$C$2)) | G18: =IF($A18="","",D18+E18-F18) | H18: =IF($A18="","",SUMIFS(Incentives!$H:$H,Incentives!$B:$B,$A18,Incentives!$N:$N,$B$2)+SUMIFS(Incentives!$H:$H,Incentives!$B:$B,$A18,Incentives!$N:$N,$C$2)) | I18: =IF($A18="","",COUNTIFS(Schedule!$G:$G,$A18,Schedule!$U:$U,$B$2,Schedule!$P:$P,">0")+COUNTIFS('TL Schedule'!$C:$C,$A18,'TL Schedule'!$K:$K,$B$2,'TL Schedule'!$J:$J,">0")+COUNTIFS(Schedule!$G:$G,$A18,Schedule!$U:$U,$C$2,Schedule!$P:$P,">0")+COUNTIFS('TL Schedule'!$C:$C,$A18,'TL Schedule'!$K:$K,$C$2,'TL Schedule'!$J:$J,">0")) | J18: =IF($A18="","",IFERROR(TEXTJOIN(", ",TRUE,UNIQUE(FILTER(Schedule!$D$2:$D50000,Schedule!$G$2:$G50000=$A18,Schedule!$P$2:$P50000>0,((Schedule!$U$2:$U50000=$B$2)+(Schedule!$U$2:$U50000=$C$2))))),""))
A19: Jefferson | B19: =IF($A19="","",SUMIFS(Schedule!$P:$P,Schedule!$G:$G,$A19,Schedule!$U:$U,$B$2)+SUMIFS('TL Schedule'!$J:$J,'TL Schedule'!$C:$C,$A19,'TL Schedule'!$K:$K,$B$2)) | C19: =IF($A19="","",SUMIFS(Schedule!$P:$P,Schedule!$G:$G,$A19,Schedule!$U:$U,$C$2)+SUMIFS('TL Schedule'!$J:$J,'TL Schedule'!$C:$C,$A19,'TL Schedule'!$K:$K,$C$2)) | D19: =IF($A19="","",B19+C19) | E19: =IF($A19="","",SUMIFS(Overtime!$H:$H,Overtime!$B:$B,$A19,Overtime!$N:$N,$B$2)+SUMIFS(Overtime!$H:$H,Overtime!$B:$B,$A19,Overtime!$N:$N,$C$2)) | F19: =IF($A19="","",SUMIFS('Death Penalty'!$E:$E,'Death Penalty'!$B:$B,$A19,'Death Penalty'!$L:$L,$B$2)+SUMIFS('Death Penalty'!$E:$E,'Death Penalty'!$B:$B,$A19,'Death Penalty'!$L:$L,$C$2)) | G19: =IF($A19="","",D19+E19-F19) | H19: =IF($A19="","",SUMIFS(Incentives!$H:$H,Incentives!$B:$B,$A19,Incentives!$N:$N,$B$2)+SUMIFS(Incentives!$H:$H,Incentives!$B:$B,$A19,Incentives!$N:$N,$C$2)) | I19: =IF($A19="","",COUNTIFS(Schedule!$G:$G,$A19,Schedule!$U:$U,$B$2,Schedule!$P:$P,">0")+COUNTIFS('TL Schedule'!$C:$C,$A19,'TL Schedule'!$K:$K,$B$2,'TL Schedule'!$J:$J,">0")+COUNTIFS(Schedule!$G:$G,$A19,Schedule!$U:$U,$C$2,Schedule!$P:$P,">0")+COUNTIFS('TL Schedule'!$C:$C,$A19,'TL Schedule'!$K:$K,$C$2,'TL Schedule'!$J:$J,">0")) | J19: =IF($A19="","",IFERROR(TEXTJOIN(", ",TRUE,UNIQUE(FILTER(Schedule!$D$2:$D50000,Schedule!$G$2:$G50000=$A19,Schedule!$P$2:$P50000>0,((Schedule!$U$2:$U50000=$B$2)+(Schedule!$U$2:$U50000=$C$2))))),""))
A20: Jel Rick | B20: =IF($A20="","",SUMIFS(Schedule!$P:$P,Schedule!$G:$G,$A20,Schedule!$U:$U,$B$2)+SUMIFS('TL Schedule'!$J:$J,'TL Schedule'!$C:$C,$A20,'TL Schedule'!$K:$K,$B$2)) | C20: =IF($A20="","",SUMIFS(Schedule!$P:$P,Schedule!$G:$G,$A20,Schedule!$U:$U,$C$2)+SUMIFS('TL Schedule'!$J:$J,'TL Schedule'!$C:$C,$A20,'TL Schedule'!$K:$K,$C$2)) | D20: =IF($A20="","",B20+C20) | E20: =IF($A20="","",SUMIFS(Overtime!$H:$H,Overtime!$B:$B,$A20,Overtime!$N:$N,$B$2)+SUMIFS(Overtime!$H:$H,Overtime!$B:$B,$A20,Overtime!$N:$N,$C$2)) | F20: =IF($A20="","",SUMIFS('Death Penalty'!$E:$E,'Death Penalty'!$B:$B,$A20,'Death Penalty'!$L:$L,$B$2)+SUMIFS('Death Penalty'!$E:$E,'Death Penalty'!$B:$B,$A20,'Death Penalty'!$L:$L,$C$2)) | G20: =IF($A20="","",D20+E20-F20) | H20: =IF($A20="","",SUMIFS(Incentives!$H:$H,Incentives!$B:$B,$A20,Incentives!$N:$N,$B$2)+SUMIFS(Incentives!$H:$H,Incentives!$B:$B,$A20,Incentives!$N:$N,$C$2)) | I20: =IF($A20="","",COUNTIFS(Schedule!$G:$G,$A20,Schedule!$U:$U,$B$2,Schedule!$P:$P,">0")+COUNTIFS('TL Schedule'!$C:$C,$A20,'TL Schedule'!$K:$K,$B$2,'TL Schedule'!$J:$J,">0")+COUNTIFS(Schedule!$G:$G,$A20,Schedule!$U:$U,$C$2,Schedule!$P:$P,">0")+COUNTIFS('TL Schedule'!$C:$C,$A20,'TL Schedule'!$K:$K,$C$2,'TL Schedule'!$J:$J,">0")) | J20: =IF($A20="","",IFERROR(TEXTJOIN(", ",TRUE,UNIQUE(FILTER(Schedule!$D$2:$D50000,Schedule!$G$2:$G50000=$A20,Schedule!$P$2:$P50000>0,((Schedule!$U$2:$U50000=$B$2)+(Schedule!$U$2:$U50000=$C$2))))),""))
A21: Jheco | B21: =IF($A21="","",SUMIFS(Schedule!$P:$P,Schedule!$G:$G,$A21,Schedule!$U:$U,$B$2)+SUMIFS('TL Schedule'!$J:$J,'TL Schedule'!$C:$C,$A21,'TL Schedule'!$K:$K,$B$2)) | C21: =IF($A21="","",SUMIFS(Schedule!$P:$P,Schedule!$G:$G,$A21,Schedule!$U:$U,$C$2)+SUMIFS('TL Schedule'!$J:$J,'TL Schedule'!$C:$C,$A21,'TL Schedule'!$K:$K,$C$2)) | D21: =IF($A21="","",B21+C21) | E21: =IF($A21="","",SUMIFS(Overtime!$H:$H,Overtime!$B:$B,$A21,Overtime!$N:$N,$B$2)+SUMIFS(Overtime!$H:$H,Overtime!$B:$B,$A21,Overtime!$N:$N,$C$2)) | F21: =IF($A21="","",SUMIFS('Death Penalty'!$E:$E,'Death Penalty'!$B:$B,$A21,'Death Penalty'!$L:$L,$B$2)+SUMIFS('Death Penalty'!$E:$E,'Death Penalty'!$B:$B,$A21,'Death Penalty'!$L:$L,$C$2)) | G21: =IF($A21="","",D21+E21-F21) | H21: =IF($A21="","",SUMIFS(Incentives!$H:$H,Incentives!$B:$B,$A21,Incentives!$N:$N,$B$2)+SUMIFS(Incentives!$H:$H,Incentives!$B:$B,$A21,Incentives!$N:$N,$C$2)) | I21: =IF($A21="","",COUNTIFS(Schedule!$G:$G,$A21,Schedule!$U:$U,$B$2,Schedule!$P:$P,">0")+COUNTIFS('TL Schedule'!$C:$C,$A21,'TL Schedule'!$K:$K,$B$2,'TL Schedule'!$J:$J,">0")+COUNTIFS(Schedule!$G:$G,$A21,Schedule!$U:$U,$C$2,Schedule!$P:$P,">0")+COUNTIFS('TL Schedule'!$C:$C,$A21,'TL Schedule'!$K:$K,$C$2,'TL Schedule'!$J:$J,">0")) | J21: =IF($A21="","",IFERROR(TEXTJOIN(", ",TRUE,UNIQUE(FILTER(Schedule!$D$2:$D50000,Schedule!$G$2:$G50000=$A21,Schedule!$P$2:$P50000>0,((Schedule!$U$2:$U50000=$B$2)+(Schedule!$U$2:$U50000=$C$2))))),""))
A22: John Carlo | B22: =IF($A22="","",SUMIFS(Schedule!$P:$P,Schedule!$G:$G,$A22,Schedule!$U:$U,$B$2)+SUMIFS('TL Schedule'!$J:$J,'TL Schedule'!$C:$C,$A22,'TL Schedule'!$K:$K,$B$2)) | C22: =IF($A22="","",SUMIFS(Schedule!$P:$P,Schedule!$G:$G,$A22,Schedule!$U:$U,$C$2)+SUMIFS('TL Schedule'!$J:$J,'TL Schedule'!$C:$C,$A22,'TL Schedule'!$K:$K,$C$2)) | D22: =IF($A22="","",B22+C22) | E22: =IF($A22="","",SUMIFS(Overtime!$H:$H,Overtime!$B:$B,$A22,Overtime!$N:$N,$B$2)+SUMIFS(Overtime!$H:$H,Overtime!$B:$B,$A22,Overtime!$N:$N,$C$2)) | F22: =IF($A22="","",SUMIFS('Death Penalty'!$E:$E,'Death Penalty'!$B:$B,$A22,'Death Penalty'!$L:$L,$B$2)+SUMIFS('Death Penalty'!$E:$E,'Death Penalty'!$B:$B,$A22,'Death Penalty'!$L:$L,$C$2)) | G22: =IF($A22="","",D22+E22-F22) | H22: =IF($A22="","",SUMIFS(Incentives!$H:$H,Incentives!$B:$B,$A22,Incentives!$N:$N,$B$2)+SUMIFS(Incentives!$H:$H,Incentives!$B:$B,$A22,Incentives!$N:$N,$C$2)) | I22: =IF($A22="","",COUNTIFS(Schedule!$G:$G,$A22,Schedule!$U:$U,$B$2,Schedule!$P:$P,">0")+COUNTIFS('TL Schedule'!$C:$C,$A22,'TL Schedule'!$K:$K,$B$2,'TL Schedule'!$J:$J,">0")+COUNTIFS(Schedule!$G:$G,$A22,Schedule!$U:$U,$C$2,Schedule!$P:$P,">0")+COUNTIFS('TL Schedule'!$C:$C,$A22,'TL Schedule'!$K:$K,$C$2,'TL Schedule'!$J:$J,">0")) | J22: =IF($A22="","",IFERROR(TEXTJOIN(", ",TRUE,UNIQUE(FILTER(Schedule!$D$2:$D50000,Schedule!$G$2:$G50000=$A22,Schedule!$P$2:$P50000>0,((Schedule!$U$2:$U50000=$B$2)+(Schedule!$U$2:$U50000=$C$2))))),""))
